Workbook
Name age_mean: covariates!$D$2:$D$123
Name age_sd: covariates!$E$2:$E$123
Name female: covariates!$G$2:$G$123
Name follow_up: covariates!$H$2:$H$123
Name male: covariates!$F$2:$F$123

Sheet outcomes
A1: id | B1: study | C1: subgroup | D1: outcome | E1: data_type | F1: ni | G1: yi | H1: sdi | I1: TE | J1: seTE | K1: age | L1: male | M1: female | N1: follow_up
A2: 6 | B2: Anz et al., 2023 | C2: BPTB | D2: graft rupture | E2: dichotomous | F2: 8 | G2: 0 | H2: 0.18 | K2: 27.6 | L2: =VLOOKUP($B2,covariates!$B$2:$H$125,5) -> 3 | M2: =VLOOKUP($B2,covariates!$B$2:$H$125,6) -> 7 | N2: 12
A3: 6 | B3: Anz et al., 2023 | C3: HT | D3: graft rupture | E3: dichotomous | F3: 8 | G3: 0 | H3: 0.18 | K3: 27.6 | L3: =VLOOKUP($B3,covariates!$B$2:$H$125,5) -> 3 | M3: =VLOOKUP($B3,covariates!$B$2:$H$125,6) -> 7 | N3: 12
A4: 43 | B4: Kautzner et al., 2015 | C4: BPTB | D4: graft rupture | E4: dichotomous | F4: 74 | G4: 0 | H4: 0.06 | K4: 26 | L4: =VLOOKUP($B4,covariates!$B$2:$H$125,5) -> 0 | M4: =VLOOKUP($B4,covariates!$B$2:$H$125,6) -> 73 | N4: 24
A5: 43 | B5: Kautzner et al., 2015 | C5: HT | D5: graft rupture | E5: dichotomous | F5: 73 | G5: 2 | H5: 0.3 | K5: 26 | L5: =VLOOKUP($B5,covariates!$B$2:$H$125,5) -> 0 | M5: =VLOOKUP($B5,covariates!$B$2:$H$125,6) -> 73 | N5: 24
A6: 49 | B6: Laxdal et al., 2005 | C6: BPTB | D6: graft rupture | E6: dichotomous | F6: 40 | G6: 1 | H6: 0.24 | K6: 25 | N6: 26
A7: 49 | B7: Laxdal et al., 2005 | C7: HT | D7: graft rupture | E7: dichotomous | F7: 78 | G7: 2 | H7: 0.42 | K7: 25 | N7: 26
A8: 54 | B8: Lucidi et al., 2025 | C8: BPTB | D8: graft rupture | E8: dichotomous | F8: 19 | G8: 7 | H8: 2.72 | K8: 54.5 | N8: 240
A9: 54 | B9: Lucidi et al., 2025 | C9: HT | D9: graft rupture | E9: dichotomous | F9: 20 | G9: 3 | H9: 0.92 | K9: 54.5 | N9: 240
A10: 66 | B10: Mohtadi et al., 2016 | C10: BPTB | D10: graft rupture | E10: dichotomous | F10: 110 | G10: 19 | H10: 2.25 | K10: 28.4 | L10: =VLOOKUP($B10,covariates!$B$2:$H$125,5) -> 120 | M10: =VLOOKUP($B10,covariates!$B$2:$H$125,6) -> 100 | N10: 24
A11: 66 | B11: Mohtadi et al., 2016 | C11: HT | D11: graft rupture | E11: dichotomous | F11: 110 | G11: 24 | H11: 2.99 | K11: 28.4 | L11: =VLOOKUP($B11,covariates!$B$2:$H$125,5) -> 120 | M11: =VLOOKUP($B11,covariates!$B$2:$H$125,6) -> 100 | N11: 24
A12: 76 | B12: Pinczewski et al., 2007 | C12: BPTB | D12: graft rupture | E12: dichotomous | F12: 90 | G12: 7 | H12: 0.86 | K12: 24 | L12: =VLOOKUP($B12,covariates!$B$2:$H$125,5) -> 47 | M12: =VLOOKUP($B12,covariates!$B$2:$H$125,6) -> 43 | N12: 120
A13: 76 | B13: Pinczewski et al., 2007 | C13: HT | D13: graft rupture | E13: dichotomous | F13: 90 | G13: 12 | H13: 1.52 | K13: 24 | L13: =VLOOKUP($B13,covariates!$B$2:$H$125,5) -> 47 | M13: =VLOOKUP($B13,covariates!$B$2:$H$125,6) -> 43 | N13: 120
A14: 77 | B14: Popovic et al., 2024 | C14: BPTB | D14: graft rupture | E14: dichotomous | F14: 38 | G14: 3 | H14: 0.62 | K14: 27 | N14: 228
A15: 77 | B15: Popovic et al., 2024 | C15: HT | D15: graft rupture | E15: dichotomous | F15: 33 | G15: 4 | H15: 0.89 | K15: 27 | N15: 228
A16: 85 | B16: Smith et al., 2020 | C16: BPTB | D16: graft rupture | E16: dichotomous | F16: 32 | G16: 0 | H16: 0.09 | K16: 17.7 | L16: =VLOOKUP($B16,covariates!$B$2:$H$125,5) -> 13 | M16: =VLOOKUP($B16,covariates!$B$2:$H$125,6) -> 19 | N16: 24
A17: 85 | B17: Smith et al., 2020 | C17: HT | D17: graft rupture | E17: dichotomous | F17: 32 | G17: 2 | H17: 0.47 | K17: 17.7 | L17: =VLOOKUP($B17,covariates!$B$2:$H$125,5) -> 13 | M17: =VLOOKUP($B17,covariates!$B$2:$H$125,6) -> 19 | N17: 24
A18: 87 | B18: Sonnery-cottet et al., 2026 | C18: BPTB | D18: graft rupture | E18: dichotomous | F18: 273 | G18: 12 | H18: 0.79 | K18: 25.2 | L18: =VLOOKUP($B18,covariates!$B$2:$H$125,5) -> 233 | M18: =VLOOKUP($B18,covariates!$B$2:$H$125,6) -> 40 | N18: 63.9
A19: 87 | B19: Sonnery-cottet et al., 2026 | C19: HT | D19: graft rupture | E19: dichotomous | F19: 283 | G19: 12 | H19: 0.78 | K19: 25.2 | L19: =VLOOKUP($B19,covariates!$B$2:$H$125,5) -> 233 | M19: =VLOOKUP($B19,covariates!$B$2:$H$125,6) -> 40 | N19: 63.9
A20: 90 | B20: Taylor et al., 2009 | C20: BPTB | D20: graft rupture | E20: dichotomous | F20: 32 | G20: 3 | H20: 0.68 | K20: 22.1 | L20: =VLOOKUP($B20,covariates!$B$2:$H$125,5) -> 28 | M20: =VLOOKUP($B20,covariates!$B$2:$H$125,6) -> 4 | N20: 38.4
A21: 90 | B21: Taylor et al., 2009 | C21: HT | D21: graft rupture | E21: dichotomous | F21: 32 | G21: 4 | H21: 0.91 | K21: 22.1 | L21: =VLOOKUP($B21,covariates!$B$2:$H$125,5) -> 28 | M21: =VLOOKUP($B21,covariates!$B$2:$H$125,6) -> 4 | N21: 38.4
A22: 96 | B22: Wipfler et al., 2011 | C22: BPTB | D22: graft rupture | E22: dichotomous | F22: 29 | G22: 3 | H22: 0.72 | K22: 34.2 | L22: =VLOOKUP($B22,covariates!$B$2:$H$125,5) -> 18 | M22: =VLOOKUP($B22,covariates!$B$2:$H$125,6) -> 13 | N22: 108
A23: 96 | B23: Wipfler et al., 2011 | C23: HT | D23: graft rupture | E23: dichotomous | F23: 25 | G23: 3 | H23: 0.8 | K23: 34.2 | L23: =VLOOKUP($B23,covariates!$B$2:$H$125,5) -> 18 | M23: =VLOOKUP($B23,covariates!$B$2:$H$125,6) -> 13 | N23: 108
A24: 97 | B24: Yadav et al., 2025 | C24: HT | D24: graft rupture | E24: dichotomous | F24: 36 | G24: 1 | H24: 0.26 | K24: 28.7 | L24: =VLOOKUP($B24,covariates!$B$2:$H$125,5) -> 30 | M24: =VLOOKUP($B24,covariates!$B$2:$H$125,6) -> 3 | N24: 12
A25: 97 | B25: Yadav et al., 2025 | C25: QT | D25: graft rupture | E25: dichotomous | F25: 33 | G25: 0 | H25: 0.09 | K25: 28.7 | L25: =VLOOKUP($B25,covariates!$B$2:$H$125,5) -> 30 | M25: =VLOOKUP($B25,covariates!$B$2:$H$125,6) -> 3 | N25: 12
A26: 10 | B26: Barié et al., 2020 | C26: BPTB | D26: ikdc_subjective | E26: continuous | F26: 43 | G26: 91 | H26: 7.3 | K26: 30.5 | L26: =VLOOKUP($B26,covariates!$B$2:$H$125,5) -> 17 | M26: =VLOOKUP($B26,covariates!$B$2:$H$125,6) -> 13 | N26: 123.6
A27: 10 | B27: Barié et al., 2020 | C27: QT | D27: ikdc_subjective | E27: continuous | F27: 43 | G27: 92 | H27: 11.5 | K27: 30.5 | L27: =VLOOKUP($B27,covariates!$B$2:$H$125,5) -> 17 | M27: =VLOOKUP($B27,covariates!$B$2:$H$125,6) -> 13 | N27: 123.6
... A49: 53 | B49: Lind et al., 2020 | C49: QT | D49: ikdc_subjective | E49: continuous | F49: 47 | G49: 82 | H49: 14 | K49: 27.2 | L49: =VLOOKUP($B49,covariates!$B$2:$H$125,5) -> 29 | M49: =VLOOKUP($B49,covariates!$B$2:$H$125,6) -> 21 | N49: 24
A50: 54 | B50: Lucidi et al., 2025 | C50: BPTB | D50: ikdc_subjective | E50: continuous | F50: 19 | G50: 78.4 | H50: 13.7 | K50: 54.5 | N50: 240
A51: 54 | B51: Lucidi et al., 2025 | C51: HT | D51: ikdc_subjective | E51: continuous | F51: 20 | G51: 81.6 | H51: 11.9 | K51: 54.5 | N51: 240
A52: 55 | B52: Lui et al., 2012 | C52: BPTB | D52: ikdc_subjective | E52: continuous | F52: 14 | G52: 71.9 | H52: 15.2 | K52: 24.6 | L52: =VLOOKUP($B52,covariates!$B$2:$H$125,5) -> 38 | M52: =VLOOKUP($B52,covariates!$B$2:$H$125,6) -> 0 | N52: 12
A53: 55 | B53: Lui et al., 2012 | C53: HT | D53: ikdc_subjective | E53: continuous | F53: 17 | G53: 73.1 | H53: 12.3 | K53: 24.6 | L53: =VLOOKUP($B53,covariates!$B$2:$H$125,5) -> 38 | M53: =VLOOKUP($B53,covariates!$B$2:$H$125,6) -> 0 | N53: 12
A54: 56 | B54: Lund et al., 2014 | C54: BPTB | D54: ikdc_subjective | E54: continuous | F54: 18 | G54: 75 | H54: 13 | K54: 30 | L54: =VLOOKUP($B54,covariates!$B$2:$H$125,5) -> 17 | M54: =VLOOKUP($B54,covariates!$B$2:$H$125,6) -> 4 | N54: 24
A55: 56 | B55: Lund et al., 2014 | C55: QT | D55: ikdc_subjective | E55: continuous | F55: 21 | G55: 76 | H55: 16 | K55: 30 | L55: =VLOOKUP($B55,covariates!$B$2:$H$125,5) -> 17 | M55: =VLOOKUP($B55,covariates!$B$2:$H$125,6) -> 4 | N55: 24
A56: 58 | B56: Malik et al., 2026 | C56: HT | D56: ikdc_subjective | E56: continuous | F56: 25 | G56: 78.9 | H56: 7.4 | K56: 27.8 | L56: =VLOOKUP($B56,covariates!$B$2:$H$125,5) -> 17 | M56: =VLOOKUP($B56,covariates!$B$2:$H$125,6) -> 8 | N56: 6
A57: 58 | B57: Malik et al., 2026 | C57: PLT | D57: ikdc_subjective | E57: continuous | F57: 25 | G57: 82.6 | H57: 6.3 | K57: 27.8 | L57: =VLOOKUP($B57,covariates!$B$2:$H$125,5) -> 17 | M57: =VLOOKUP($B57,covariates!$B$2:$H$125,6) -> 8 | N57: 6
A58: 62 | B58: Matsumoto et al., 2006 | C58: BPTB | D58: ikdc_subjective | E58: continuous | F58: 37 | G58: 84.3 | H58: 11 | K58: 24.4 | L58: =VLOOKUP($B58,covariates!$B$2:$H$125,5) -> 20 | M58: =VLOOKUP($B58,covariates!$B$2:$H$125,6) -> 15 | N58: 80.7
A59: 62 | B59: Matsumoto et al., 2006 | C59: HT | D59: ikdc_subjective | E59: continuous | F59: 35 | G59: 86.8 | H59: 8.3 | K59: 24.4 | L59: =VLOOKUP($B59,covariates!$B$2:$H$125,5) -> 20 | M59: =VLOOKUP($B59,covariates!$B$2:$H$125,6) -> 15 | N59: 80.7
A60: 68 | B60: Moraiti et al., 2010 | C60: BPTB | D60: ikdc_subjective | E60: continuous | F60: 6 | G60: 92 | H60: 7 | K60: 24 | L60: =VLOOKUP($B60,covariates!$B$2:$H$125,5) -> 6 | M60: =VLOOKUP($B60,covariates!$B$2:$H$125,6) -> 0 | N60: 25
A61: 68 | B61: Moraiti et al., 2010 | C61: HT | D61: ikdc_subjective | E61: continuous | F61: 6 | G61: 90 | H61: 10 | K61: 24 | L61: =VLOOKUP($B61,covariates!$B$2:$H$125,5) -> 6 | M61: =VLOOKUP($B61,covariates!$B$2:$H$125,6) -> 0 | N61: 25
...

Sheet covariates
A1: id | B1: study | C1: subgroup | D1: age_mean | E1: age_sd | F1: male | G1: female | H1: follow_up
A2: 1 | B2: Ageberg et al., 2009 | C2: BPTB | D2: 32 | E2: 5 | F2: 15 | G2: 5 | H2: 36
A3: 1 | B3: Ageberg et al., 2009 | C3: HT | D3: 28 | E3: 4.4 | F3: 12 | G3: 4 | H3: 36
A4: 2 | B4: Aglietti et al., 2004 | C4: BPTB | D4: 25 | E4: 5 | F4: 46 | G4: 14 | H4: 24
A5: 2 | B5: Aglietti et al., 2004 | C5: HT | D5: 25 | E5: 5.2 | F5: 46 | G5: 14 | H5: 24
A6: 3 | B6: Ahldén et al., 2009 | C6: BPTB | D6: 27.4 | E6: 8.9 | F6: 14 | G6: 8 | H6: 90.3
A7: 3 | B7: Ahldén et al., 2009 | C7: HT | D7: 28.6 | E7: 6.4 | F7: 18 | G7: 7 | H7: 86.8
A8: 5 | B8: Anderson et al., 2001 | C8: BPTB | D8: 23.6 | E8: 7.1 | F8: 23 | G8: 12 | H8: 34.6
A9: 5 | B9: Anderson et al., 2001 | C9: 2-STG + LET | D9: 22 | E9: 5.8 | F9: 22 | G9: 11 | H9: 35.7
A10: 5 | B10: Anderson et al., 2001 | C10: 2-STG | D10: 20.1 | E10: 5.8 | F10: 23 | G10: 12 | H10: 35.9
A11: 5 | B11: Anderson et al., 2001 | C11: HT | D11: 21 | E11: 5.8 | F11: 45 | G11: 23 | H11: 35.8
A12: 6 | B12: Anz et al., 2023 | C12: BPTB | D12: 29.4 | E12: 7.3 | F12: 4 | G12: 6 | H12: 12
A13: 6 | B13: Anz et al., 2023 | C13: HT | D13: 27.6 | E13: 8.6 | F13: 3 | G13: 7 | H13: 12
... A33: 23 | B33: Ejerhed et al., 2003 | C33: HT | D33: 30.8 | E33: 10.5 | F33: 25 | G33: 9 | H33: 24
A34: 25 | B34: Eriksson et al., 2001 | C34: BPTB | D34: 27 | E34: 6 | H34: 6.7
A35: 25 | B35: Eriksson et al., 2001 | C35: HT | D35: 27 | E35: 6 | H35: 6.7
A36: 26 | B36: Feller & Webster, 2003 | C36: BPTB | D36: 25.8 | E36: 6 | F36: 23 | G36: 8 | H36: 36
A37: 26 | B37: Feller & Webster, 2003 | C37: HT | D37: 26.3 | E37: 6 | F37: 24 | G37: 10 | H37: 36
A38: 30 | B38: Gifstad et al., 2013 | C38: BPTB | D38: 27 | E38: 6.7 | H38: 84
A39: 30 | B39: Gifstad et al., 2013 | C39: HT | D39: 27 | E39: 6.8 | H39: 84
A40: 32 | B40: Guglielmetti et al., 2021 | C40: BPTB | D40: 25.2 | E40: 5.5 | F40: 23 | G40: 8 | H40: 24
A41: 32 | B41: Guglielmetti et al., 2021 | C41: HT | D41: 24.6 | E41: 5.3 | F41: 19 | G41: 12 | H41: 24
A42: 33 | B42: Harilainen et al., 2006 | C42: BPTB | H42: 60.6
A43: 33 | B43: Harilainen et al., 2006 | C43: HT | H43: 60.6
A44: 34 | B44: Heijne & Werner, 2010 | C44: BPTB | D44: 29 | E44: 7 | F44: 22 | G44: 12 | H44: 24.7
A45: 34 | B45: Heijne & Werner, 2010 | C45: HT | D45: 30 | E45: 9 | F45: 14 | G45: 20 | H45: 24.7
A46: 35 | B46: Holm et al., 2010 | C46: BPTB | D46: 33.9 | E46: 6.2 | F46: 18 | G46: 10 | H46: 10.2
A47: 35 | B47: Holm et al., 2010 | C47: HT | D47: 37.9 | E47: 9.1 | F47: 15 | G47: 14 | H47: 10.7
A48: 36 | B48: Horstmann et al., 2022 | C48: HT | D48: 32.7 | E48: 11.4 | F48: 12 | G48: 15 | H48: 24
A49: 36 | B49: Horstmann et al., 2022 | C49: QT | D49: 24.1 | E49: 3.6 | F49: 21 | G49: 3 | H49: 24
A50: 37 | B50: Ibrahim et al., 2005 | C50: BPTB | D50: 22.3 | E50: 3.9 | F50: 40 | G50: 0 | H50: 81
A51: 37 | B51: Ibrahim et al., 2005 | C51: HT | D51: 22.3 | E51: 3.8 | F51: 46 | G51: 0 | H51: 81
A52: 38 | B52: Iliopoulos et al., 2017 | C52: BPTB | D52: 24.8 | E52: 5 | F52: 10 | G52: 0 | H52: 9
A53: 38 | B53: Iliopoulos et al., 2017 | C53: HT | D53: 26.7 | E53: 7.2 | F53: 10 | G53: 0 | H53: 9
A54: 41 | B54: Jansson et al., 2003 | C54: BPTB | H54: 24
A55: 41 | B55: Jansson et al., 2003 | C55: HT | H55: 24
A56: 43 | B56: Kautzner et al., 2015 | C56: BPTB | D56: 26 | E56: 6.3 | F56: 0 | G56: 74 | H56: 24
A57: 43 | B57: Kautzner et al., 2015 | C57: HT | D57: 26 | E57: 6.3 | F57: 0 | G57: 73 | H57: 24
A58: 44 | B58: Komzak et al., 2022 | C58: BPTB | D58: 31 | E58: 9.5 | F58: 23 | G58: 17 | H58: 28
A59: 44 | B59: Komzak et al., 2022 | C59: QT | D59: 29.8 | E59: 9.5 | F59: 21 | G59: 19 | H59: 28
...
