Workbook
Name covariates: covariates!$A$1:$H$124
Name full_text_screening: 'screening 1.0'!$E$2:$E$101
Name study: 'screening 1.0'!$D$2:$D$101
Name subgroups: 'screening 1.0'!$C$2:$C$101
Name outcomes: 'screening 1.0'!$F$2:$F$101
Name ID: LAMBDA(id, range, IFERROR(ARRAYFORMULA(IF(range<>"",ROW(ID)-1,"")),""))
Name P_SD: LAMBDA(n, k, (((k+0.5)/(n+0.5))/((1-(k+0.5)/(n+0.5)))*SQRT(n)))
Name QUOTES: LAMBDA(string, text, string&text&string)
Name COMBINE_SD: LAMBDA(n_1, n_2, sd_1, sd_2, m_1, m_2, SQRT((((n_1-1)*(sd_1^2))+((n_2-1)*(sd_2^2))+((n_1*n_2)/(n_1+n_2))*((m_1^2)+(m_2^2)-(2*m_1*m_2)))/((n_1+n_2-1))))
Name MEDIAN_MEAN: LAMBDA(n, a, m, b, (4/(4+n^0.75))*((a+b)/2)+(n^0.75/(4+n^0.75))*m)
Name REFERENCE_LINK: LAMBDA(id, doi, HYPERLINK("https://doi.org/"&doi,id))
Name FUNCTION4: LAMBDA(range3, range4, range5, BYROW(range5, LAMBDA(sym, TEXTJOIN(", ", TRUE, FILTER(range3, range4 = sym)))))
Name CI_SD: LAMBDA(n, ci_ul, ci_ll, ((ci_ul-ci_ll)/3.92)*(SQRT(n)))
Name PLNUSD: LAMBDA(pln, if(pln<>"",GOOGLEFINANCE("PLNUSD")*pln,""))
Name USDPLN: LAMBDA(usd, if(usd<>"",GOOGLEFINANCE("USDPLN")*usd,""))
Name MANY_TO_MANY: LAMBDA(range5, range1, range2, IFERROR(BYROW(range5, LAMBDA(sym, TEXTJOIN(", ", TRUE, FILTER(FUNCTION1(range1,range2), FUNCTION2(range1,range2) = sym)))),""))
Name NUM_AUTHORS: LAMBDA(authors, nondelimiters, delimiter, IFARRAY(counta(split(regexreplace(authors,"["&nondelimiters&"]",""),delimiter&" ",false))))
Name FUNCTION3: LAMBDA(range4, iferror(unique(range4),""))
Name IFARRAY: LAMBDA(formula, iferror(arrayformula(formula),""))
Name RANGE_SD: LAMBDA(n, a, b, round(((b-a)/(2*NORM.S.INV((n-0.375)/(n+0.25)))),3))
Name BOOLEAN: LAMBDA(quotes, string, field, operator, IFERROR(ARRAYFORMULA(quotes&string&quotes&"["&field&"]"&" "&operator&" "),""))
Name DENORM: LAMBDA(junction_table, id_column, BYROW(id_column, LAMBDA(column, TEXTJOIN(", ", TRUE, FILTER(junction_table = column)))))

Sheet master
A1: id | B1: study | C1: id | D1: subgroup | E1: outcome | F1: data_type | G1: n | H1: mean | I1: sd | J1: age | K1: male | L1: female | M1: follow_up
A2: 6 | B2: =HYPERLINK("https://github.com/d-wkim/phd/blob/main/data/pdf/anz_2023.pdf","Anz et al., 2023") -> Anz et al., 2023 | C2: 6 | D2: BPTB | E2: graft rupture | F2: dichotomous | G2: 8 | H2: 0 | I2: =iferror(P_SD(G2,H2),"") -> 0.1767767 | J2: =VLOOKUP($A2,covariates!$A$3:$Z$1126,6,false) | K2: =VLOOKUP($A2,covariates!$A$3:$H$1126,5,false) -> at surgery | L2: =VLOOKUP($A2,covariates!$A$3:$H$1126,5,false) -> at surgery | M2: =VLOOKUP($A2,covariates!$A$3:$H$1126,5,false) -> at surgery
A3: 6 | B3: =HYPERLINK("https://github.com/d-wkim/phd/blob/main/data/pdf/anz_2023.pdf","Anz et al., 2023") -> Anz et al., 2023 | C3: 6 | D3: HT | E3: graft rupture | F3: dichotomous | G3: 8 | H3: 0 | I3: =iferror(P_SD(G3,H3),"") -> 0.1767767 | J3: =VLOOKUP($A3,covariates!$A$3:$H$1126,5,false) -> at surgery | L3: =VLOOKUP($A3,covariates!$A$3:$H$1126,6,false) | M3: =VLOOKUP($A3,covariates!$A$3:$H$1126,6,false)
A4: 43 | B4: =HYPERLINK("https://github.com/d-wkim/phd/blob/main/data/pdf/kautzner_2015.pdf","Kautzner et al., 2015") -> Kautzner et al., 2015 | C4: 43 | D4: BPTB | E4: graft rupture | F4: dichotomous | G4: 74 | H4: 0 | I4: =iferror(P_SD(G4,H4),"") -> 0.058123819 | J4: =VLOOKUP($A4,covariates!$A$3:$H$1126,5,false) -> at surgery | L4: =VLOOKUP($A4,covariates!$A$3:$H$1126,6,false) | M4: =VLOOKUP($A4,covariates!$A$3:$H$1126,6,false)
A5: 43 | B5: =HYPERLINK("https://github.com/d-wkim/phd/blob/main/data/pdf/kautzner_2015.pdf","Kautzner et al., 2015") -> Kautzner et al., 2015 | C5: 43 | D5: HT | E5: graft rupture | F5: dichotomous | G5: 73 | H5: 2 | I5: =iferror(P_SD(G5,H5),"") -> 0.3008452 | J5: =VLOOKUP($A5,covariates!$A$3:$H$1126,5,false) -> at surgery | L5: =VLOOKUP($A5,covariates!$A$3:$H$1126,6,false) | M5: =VLOOKUP($A5,covariates!$A$3:$H$1126,6,false)
A6: 49 | B6: =HYPERLINK("https://github.com/d-wkim/phd/blob/main/data/pdf/laxdal_2005.pdf","Laxdal et al., 2005") -> Laxdal et al., 2005 | C6: 49 | D6: BPTB | E6: graft rupture | F6: dichotomous | G6: 40 | H6: 1 | I6: =iferror(P_SD(G6,H6),"") -> 0.24325213 | J6: =VLOOKUP($A6,covariates!$A$3:$H$1126,5,false) -> at surgery | L6: =VLOOKUP($A6,covariates!$A$3:$H$1126,6,false) | M6: =VLOOKUP($A6,covariates!$A$3:$H$1126,6,false)
A7: 49 | B7: =HYPERLINK("https://github.com/d-wkim/phd/blob/main/data/pdf/laxdal_2005.pdf","Laxdal et al., 2005") -> Laxdal et al., 2005 | C7: 49 | D7: HT | E7: graft rupture | F7: dichotomous | G7: 78 | H7: 2 | I7: 0.42059596 | J7: =VLOOKUP($A7,covariates!$A$3:$H$1126,5,false) -> at surgery | L7: =VLOOKUP($A7,covariates!$A$3:$H$1126,6,false) | M7: =VLOOKUP($A7,covariates!$A$3:$H$1126,6,false)
A8: 54 | B8: =HYPERLINK("https://github.com/d-wkim/phd/blob/main/data/pdf/lucidi_2025.pdf","Lucidi et al., 2025") -> Lucidi et al., 2025 | C8: 54 | D8: BPTB | E8: graft rupture | F8: dichotomous | G8: 19 | H8: 7 | I8: =iferror(P_SD(G8,H8),"") -> 2.7243118 | J8: =VLOOKUP($A8,covariates!$A$3:$H$1126,5,false) -> at surgery | L8: =VLOOKUP($A8,covariates!$A$3:$H$1126,6,false) | M8: =VLOOKUP($A8,covariates!$A$3:$H$1126,6,false)
A9: 54 | B9: =HYPERLINK("https://github.com/d-wkim/phd/blob/main/data/pdf/lucidi_2025.pdf","Lucidi et al., 2025") -> Lucidi et al., 2025 | C9: 54 | D9: HT | E9: graft rupture | F9: dichotomous | G9: 20 | H9: 3 | I9: =iferror(P_SD(G9,H9),"") -> 0.92073387 | J9: =VLOOKUP($A9,covariates!$A$3:$H$1126,5,false) -> at surgery | L9: =VLOOKUP($A9,covariates!$A$3:$H$1126,6,false) | M9: =VLOOKUP($A9,covariates!$A$3:$H$1126,6,false)
A10: 66 | B10: =HYPERLINK("https://github.com/d-wkim/phd/blob/main/data/pdf/mohtadi_2016a.pdf","Mohtadi et al., 2016") -> Mohtadi et al., 2016 | C10: 66 | D10: BPTB | E10: graft rupture | F10: dichotomous | G10: 110 | H10: 19 | I10: =iferror(P_SD(G10,H10),"") -> 2.2474475 | J10: =VLOOKUP($A10,covariates!$A$3:$H$1126,5,false) -> at surgery | L10: =VLOOKUP($A10,covariates!$A$3:$H$1126,6,false) | M10: =VLOOKUP($A10,covariates!$A$3:$H$1126,6,false)
A11: 66 | B11: =HYPERLINK("https://github.com/d-wkim/phd/blob/main/data/pdf/mohtadi_2016a.pdf","Mohtadi et al., 2016") -> Mohtadi et al., 2016 | C11: 66 | D11: HT | E11: graft rupture | F11: dichotomous | G11: 110 | H11: 24 | I11: =iferror(P_SD(G11,H11),"") -> 2.9878857 | J11: =VLOOKUP($A11,covariates!$A$3:$H$1126,5,false) -> at surgery | L11: =VLOOKUP($A11,covariates!$A$3:$H$1126,6,false) | M11: =VLOOKUP($A11,covariates!$A$3:$H$1126,6,false)
A12: 76 | B12: =HYPERLINK("https://github.com/d-wkim/phd/blob/main/data/pdf/pinczewski_2007.pdf","Pinczewski et al., 2007") -> Pinczewski et al., 2007 | C12: 76 | D12: BPTB | E12: graft rupture | F12: dichotomous | G12: 90 | H12: 7 | I12: =iferror(P_SD(G12,H12),"") -> 0.85724394 | J12: =VLOOKUP($A12,covariates!$A$3:$H$1126,5,false) -> at surgery | L12: =VLOOKUP($A12,covariates!$A$3:$H$1126,6,false) | M12: =VLOOKUP($A12,covariates!$A$3:$H$1126,6,false)
A13: 76 | B13: =HYPERLINK("https://github.com/d-wkim/phd/blob/main/data/pdf/pinczewski_2007.pdf","Pinczewski et al., 2007") -> Pinczewski et al., 2007 | C13: 76 | D13: HT | E13: graft rupture | F13: dichotomous | G13: 90 | H13: 12 | I13: =iferror(P_SD(G13,H13),"") -> 1.5203258 | J13: =VLOOKUP($A13,covariates!$A$3:$H$1126,5,false) -> at surgery | L13: =VLOOKUP($A13,covariates!$A$3:$H$1126,6,false) | M13: =VLOOKUP($A13,covariates!$A$3:$H$1126,6,false)
A14: 77 | B14: =HYPERLINK("https://github.com/d-wkim/phd/blob/main/data/pdf/popovic_2024.pdf","Popovic et al., 2024") -> Popovic et al., 2024 | C14: 77 | D14: BPTB | E14: graft rupture | F14: dichotomous | G14: 38 | H14: 3 | I14: =iferror(P_SD(G14,H14),"") -> 0.6164414 | J14: =VLOOKUP($A14,covariates!$A$3:$H$1126,5,false) -> at surgery | L14: =VLOOKUP($A14,covariates!$A$3:$H$1126,6,false) | M14: =VLOOKUP($A14,covariates!$A$3:$H$1126,6,false)
A15: 77 | B15: =HYPERLINK("https://github.com/d-wkim/phd/blob/main/data/pdf/popovic_2024.pdf","Popovic et al., 2024") -> Popovic et al., 2024 | C15: 77 | D15: HT | E15: graft rupture | F15: dichotomous | G15: 33 | H15: 4 | I15: =iferror(P_SD(G15,H15),"") -> 0.89139765 | J15: =VLOOKUP($A15,covariates!$A$3:$H$1126,5,false) -> at surgery | L15: =VLOOKUP($A15,covariates!$A$3:$H$1126,6,false) | M15: =VLOOKUP($A15,covariates!$A$3:$H$1126,6,false)
A16: 85 | B16: =HYPERLINK("https://github.com/d-wkim/phd/blob/main/data/pdf/smith_2020.pdf","Smith et al., 2020") -> Smith et al., 2020 | C16: 85 | D16: BPTB | E16: graft rupture | F16: dichotomous | G16: 32 | H16: 0 | I16: =iferror(P_SD(G16,H16),"") -> 0.088388348 | J16: =VLOOKUP($A16,covariates!$A$3:$H$1126,5,false) -> at surgery | L16: =VLOOKUP($A16,covariates!$A$3:$H$1126,6,false) | M16: =VLOOKUP($A16,covariates!$A$3:$H$1126,6,false)
A17: 85 | B17: =HYPERLINK("https://github.com/d-wkim/phd/blob/main/data/pdf/smith_2020.pdf","Smith et al., 2020") -> Smith et al., 2020 | C17: 85 | D17: HT | E17: graft rupture | F17: dichotomous | G17: 32 | H17: 2 | I17: =iferror(P_SD(G17,H17),"") -> 0.47140452 | J17: =VLOOKUP($A17,covariates!$A$3:$H$1126,5,false) -> at surgery | L17: =VLOOKUP($A17,covariates!$A$3:$H$1126,6,false) | M17: =VLOOKUP($A17,covariates!$A$3:$H$1126,6,false)
A18: 87 | B18: =HYPERLINK("https://github.com/d-wkim/phd/blob/main/data/pdf/sonnery-cottet_2026.pdf","Sonnery-cottet et al., 2026") -> Sonnery-cottet et al., 2026 | C18: 87 | D18: BPTB | E18: graft rupture | F18: dichotomous | G18: 273 | H18: 12 | I18: =iferror(P_SD(G18,H18),"") -> 0.79131761 | J18: =VLOOKUP($A18,covariates!$A$3:$H$1126,5,false) -> at surgery | L18: =VLOOKUP($A18,covariates!$A$3:$H$1126,6,false) | M18: =VLOOKUP($A18,covariates!$A$3:$H$1126,6,false)
A19: 87 | B19: =HYPERLINK("https://github.com/d-wkim/phd/blob/main/data/pdf/sonnery-cottet_2026.pdf","Sonnery-cottet et al., 2026") -> Sonnery-cottet et al., 2026 | C19: 87 | D19: HT | E19: graft rupture | F19: dichotomous | G19: 283 | H19: 12 | I19: =iferror(P_SD(G19,H19),"") -> 0.77595036 | J19: =VLOOKUP($A19,covariates!$A$3:$H$1126,5,false) -> at surgery | L19: =VLOOKUP($A19,covariates!$A$3:$H$1126,6,false) | M19: =VLOOKUP($A19,covariates!$A$3:$H$1126,6,false)
A20: 90 | B20: =HYPERLINK("https://github.com/d-wkim/phd/blob/main/data/pdf/taylor_2009.pdf","Taylor et al., 2009") -> Taylor et al., 2009 | C20: 90 | D20: BPTB | E20: graft rupture | F20: dichotomous | G20: 32 | H20: 3 | I20: =iferror(P_SD(G20,H20),"") -> 0.68272379 | J20: =VLOOKUP($A20,covariates!$A$3:$H$1126,5,false) -> at surgery | L20: =VLOOKUP($A20,covariates!$A$3:$H$1126,6,false) | M20: =VLOOKUP($A20,covariates!$A$3:$H$1126,6,false)
A21: 90 | B21: =HYPERLINK("https://github.com/d-wkim/phd/blob/main/data/pdf/taylor_2009.pdf","Taylor et al., 2009") -> Taylor et al., 2009 | C21: 90 | D21: HT | E21: graft rupture | F21: dichotomous | G21: 32 | H21: 4 | I21: =iferror(P_SD(G21,H21),"") -> 0.90913729 | J21: =VLOOKUP($A21,covariates!$A$3:$H$1126,5,false) -> at surgery | L21: =VLOOKUP($A21,covariates!$A$3:$H$1126,6,false) | M21: =VLOOKUP($A21,covariates!$A$3:$H$1126,6,false)
A22: 96 | B22: =HYPERLINK("https://github.com/d-wkim/phd/blob/main/data/pdf/wipfler_2011.pdf","Wipfler et al., 2011") -> Wipfler et al., 2011 | C22: 96 | D22: BPTB | E22: graft rupture | F22: dichotomous | G22: 29 | H22: 3 | I22: =iferror(P_SD(G22,H22),"") -> 0.72492603 | J22: =VLOOKUP($A22,covariates!$A$3:$H$1126,5,false) -> at surgery | L22: =VLOOKUP($A22,covariates!$A$3:$H$1126,6,false) | M22: =VLOOKUP($A22,covariates!$A$3:$H$1126,6,false)
A23: 96 | B23: =HYPERLINK("https://github.com/d-wkim/phd/blob/main/data/pdf/wipfler_2011.pdf","Wipfler et al., 2011") -> Wipfler et al., 2011 | C23: 96 | D23: HT | E23: graft rupture | F23: dichotomous | G23: 25 | H23: 3 | I23: =iferror(P_SD(G23,H23),"") -> 0.79545455 | J23: =VLOOKUP($A23,covariates!$A$3:$H$1126,5,false) -> at surgery | L23: =VLOOKUP($A23,covariates!$A$3:$H$1126,6,false) | M23: =VLOOKUP($A23,covariates!$A$3:$H$1126,6,false)
A24: 97 | B24: =HYPERLINK("https://github.com/d-wkim/phd/blob/main/data/pdf/yadav_2025.pdf","Yadav et al., 2025") -> Yadav et al., 2025 | C24: 97 | D24: HT | E24: graft rupture | F24: dichotomous | G24: 36 | H24: 1 | I24: =iferror(P_SD(G24,H24),"") -> 0.25714286 | J24: =VLOOKUP($A24,covariates!$A$3:$H$1126,5,false) -> at surgery | L24: =VLOOKUP($A24,covariates!$A$3:$H$1126,6,false) | M24: =VLOOKUP($A24,covariates!$A$3:$H$1126,6,false)
A25: 97 | B25: =HYPERLINK("https://github.com/d-wkim/phd/blob/main/data/pdf/yadav_2025.pdf","Yadav et al., 2025") -> Yadav et al., 2025 | C25: 97 | D25: QT | E25: graft rupture | F25: dichotomous | G25: 33 | H25: 0 | I25: =iferror(P_SD(G25,H25),"") -> 0.087038828 | J25: =VLOOKUP($A25,covariates!$A$3:$H$1126,5,false) -> at surgery | L25: =VLOOKUP($A25,covariates!$A$3:$H$1126,6,false) | M25: =VLOOKUP($A25,covariates!$A$3:$H$1126,6,false)
A26: 10 | B26: =HYPERLINK("https://github.com/d-wkim/phd/blob/main/data/pdf/barié_2020.pdf","Barié et al., 2020") -> Barié et al., 2020 | C26: 10 | D26: BPTB | E26: ikdc_subjective | F26: continuous | G26: 43 | H26: 91 | I26: 7.3 | J26: =VLOOKUP($A26,covariates!$A$3:$H$1126,5,false) -> at surgery | K26: =VLOOKUP($A26,covariates!$A$3:$H$1126,6,false) | L26: =VLOOKUP($A26,covariates!$A$3:$H$1126,7,false) -> 30.6 | M26: =VLOOKUP($A26,covariates!$A$3:$H$1126,8,false) -> 7.5
A27: 10 | B27: =HYPERLINK("https://github.com/d-wkim/phd/blob/main/data/pdf/barié_2020.pdf","Barié et al., 2020") -> Barié et al., 2020 | C27: 10 | D27: QT | E27: ikdc_subjective | F27: continuous | G27: 43 | H27: 92 | I27: 11.5 | J27: =VLOOKUP($A27,covariates!$A$3:$H$1126,5,false) -> at surgery | K27: =VLOOKUP($A27,covariates!$A$3:$H$1126,6,false) | L27: =VLOOKUP($A27,covariates!$A$3:$H$1126,7,false) -> 30.6 | M27: =VLOOKUP($A27,covariates!$A$3:$H$1126,8,false) -> 7.5
A28: 12 | B28: =HYPERLINK("https://github.com/d-wkim/phd/blob/main/data/pdf/bi_2018.pdf","Bi et al., 2018") -> Bi et al., 2018 | C28: 12 | D28: HT | E28: ikdc_subjective | F28: continuous | G28: 62 | H28: 90.4 | I28: 7.1 | J28: =VLOOKUP($A28,covariates!$A$3:$H$1126,5,false) -> at surgery | K28: =VLOOKUP($A28,covariates!$A$3:$H$1126,6,false) | L28: =VLOOKUP($A28,covariates!$A$3:$H$1126,7,false) -> 27.9 | M28: =VLOOKUP($A28,covariates!$A$3:$H$1126,8,false) -> 6.7
A29: 12 | B29: =HYPERLINK("https://github.com/d-wkim/phd/blob/main/data/pdf/bi_2018.pdf","Bi et al., 2018") -> Bi et al., 2018 | C29: 12 | D29: PLT | E29: ikdc_subjective | F29: continuous | G29: 62 | H29: 89.3 | I29: 8.4 | J29: =VLOOKUP($A29,covariates!$A$3:$H$1126,5,false) -> at surgery | K29: =VLOOKUP($A29,covariates!$A$3:$H$1126,6,false) | L29: =VLOOKUP($A29,covariates!$A$3:$H$1126,7,false) -> 27.9 | M29: =VLOOKUP($A29,covariates!$A$3:$H$1126,8,false) -> 6.7
A30: 13 | B30: =HYPERLINK("https://github.com/d-wkim/phd/blob/main/data/pdf/björnsson_2016.pdf","Björnsson et al., 2016") -> Björnsson et al., 2016 | C30: 13 | D30: BPTB | E30: ikdc_subjective | F30: continuous | G30: 61 | H30: 67.3 | I30: 20.8 | J30: =VLOOKUP($A30,covariates!$A$3:$H$1126,5,false) -> at surgery | K30: =VLOOKUP($A30,covariates!$A$3:$H$1126,6,false) | L30: =VLOOKUP($A30,covariates!$A$3:$H$1126,7,false) -> 28.2 | M30: =VLOOKUP($A30,covariates!$A$3:$H$1126,8,false) -> 9.1
A31: 13 | B31: =HYPERLINK("https://github.com/d-wkim/phd/blob/main/data/pdf/björnsson_2016.pdf","Björnsson et al., 2016") -> Björnsson et al., 2016 | C31: 13 | D31: HT | E31: ikdc_subjective | F31: continuous | G31: 86 | H31: 74 | I31: 18.8 | J31: =VLOOKUP($A31,covariates!$A$3:$H$1126,5,false) -> at surgery | K31: =VLOOKUP($A31,covariates!$A$3:$H$1126,6,false) | L31: =VLOOKUP($A31,covariates!$A$3:$H$1126,7,false) -> 28.2 | M31: =VLOOKUP($A31,covariates!$A$3:$H$1126,8,false) -> 9.1
A32: 14 | B32: =HYPERLINK("https://github.com/d-wkim/phd/blob/main/data/pdf/bottoni_2015.pdf","Bottoni et al., 2015") -> Bottoni et al., 2015 | C32: 14 | D32: HT | E32: ikdc_subjective | F32: continuous | G32: 44 | H32: 79.5 | I32: 24.7 | J32: =VLOOKUP($A32,covariates!$A$3:$H$1126,5,false) -> at surgery | K32: =VLOOKUP($A32,covariates!$A$3:$H$1126,6,false) | L32: =VLOOKUP($A32,covariates!$A$3:$H$1126,7,false) -> 28.9 | M32: =VLOOKUP($A32,covariates!$A$3:$H$1126,8,false) -> 5.8
A33: 14 | B33: =HYPERLINK("https://github.com/d-wkim/phd/blob/main/data/pdf/bottoni_2015.pdf","Bottoni et al., 2015") -> Bottoni et al., 2015 | C33: 14 | D33: TA | E33: ikdc_subjective | F33: continuous | G33: 36 | H33: 81.1 | I33: 23.1 | J33: =VLOOKUP($A33,covariates!$A$3:$H$1126,5,false) -> at surgery | K33: =VLOOKUP($A33,covariates!$A$3:$H$1126,6,false) | L33: =VLOOKUP($A33,covariates!$A$3:$H$1126,7,false) -> 28.9 | M33: =VLOOKUP($A33,covariates!$A$3:$H$1126,8,false) -> 5.8
A34: 18 | B34: =HYPERLINK("https://github.com/d-wkim/phd/blob/main/data/pdf/butt_2024.pdf","Butt et al., 2024") -> Butt et al., 2024 | C34: 18 | D34: HT | E34: ikdc_subjective | F34: continuous | G34: 30 | H34: 89.7 | I34: 5.7 | J34: =VLOOKUP($A34,covariates!$A$3:$H$1126,5,false) -> at surgery | K34: =VLOOKUP($A34,covariates!$A$3:$H$1126,6,false) | L34: =VLOOKUP($A34,covariates!$A$3:$H$1126,7,false) -> 29.17 | M34: =VLOOKUP($A34,covariates!$A$3:$H$1126,8,false) -> 5.03
A35: 18 | B35: =HYPERLINK("https://github.com/d-wkim/phd/blob/main/data/pdf/butt_2024.pdf","Butt et al., 2024") -> Butt et al., 2024 | C35: 18 | D35: PLT | E35: ikdc_subjective | F35: continuous | G35: 30 | H35: 89.9 | I35: 9.8 | J35: =VLOOKUP($A35,covariates!$A$3:$H$1126,5,false) -> at surgery | K35: =VLOOKUP($A35,covariates!$A$3:$H$1126,6,false) | L35: =VLOOKUP($A35,covariates!$A$3:$H$1126,7,false) -> 29.17 | M35: =VLOOKUP($A35,covariates!$A$3:$H$1126,8,false) -> 5.03
A36: 19 | B36: =HYPERLINK("https://github.com/d-wkim/phd/blob/main/data/pdf/calvert_2025.pdf","Calvert et al., 2025") -> Calvert et al., 2025 | C36: 19 | D36: HT | E36: ikdc_subjective | F36: continuous | G36: 92 | H36: 92 | I36: 8 | J36: =VLOOKUP($A36,covariates!$A$3:$H$1126,5,false) -> at surgery | K36: =VLOOKUP($A36,covariates!$A$3:$H$1126,6,false) | L36: =VLOOKUP($A36,covariates!$A$3:$H$1126,7,false) -> 29.4 | M36: =VLOOKUP($A36,covariates!$A$3:$H$1126,8,false) -> 7.7
A37: 19 | B37: =HYPERLINK("https://github.com/d-wkim/phd/blob/main/data/pdf/calvert_2025.pdf","Calvert et al., 2025") -> Calvert et al., 2025 | C37: 19 | D37: QT | E37: ikdc_subjective | F37: continuous | G37: 89 | H37: 89 | I37: 10 | J37: =VLOOKUP($A37,covariates!$A$3:$H$1126,5,false) -> at surgery | K37: =VLOOKUP($A37,covariates!$A$3:$H$1126,6,false) | L37: =VLOOKUP($A37,covariates!$A$3:$H$1126,7,false) -> 29.4 | M37: =VLOOKUP($A37,covariates!$A$3:$H$1126,8,false) -> 7.7
A38: 32 | B38: =HYPERLINK("https://github.com/d-wkim/phd/blob/main/data/pdf/guglielmetti_2021.pdf","Guglielmetti et al., 2021") -> Guglielmetti et al., 2021 | C38: 32 | D38: BPTB | E38: ikdc_subjective | F38: continuous | G38: 31 | H38: 88.75 | I38: 9.27 | J38: =VLOOKUP($A38,covariates!$A$3:$H$1126,5,false) -> at surgery | K38: =VLOOKUP($A38,covariates!$A$3:$H$1126,6,false) | L38: =VLOOKUP($A38,covariates!$A$3:$H$1126,7,false) -> 25.2 | M38: =VLOOKUP($A38,covariates!$A$3:$H$1126,8,false) -> 5.48
A39: 32 | B39: =HYPERLINK("https://github.com/d-wkim/phd/blob/main/data/pdf/guglielmetti_2021.pdf","Guglielmetti et al., 2021") -> Guglielmetti et al., 2021 | C39: 32 | D39: HT | E39: ikdc_subjective | F39: continuous | G39: 31 | H39: 91 | I39: 9.07 | J39: =VLOOKUP($A39,covariates!$A$3:$H$1126,5,false) -> at surgery | K39: =VLOOKUP($A39,covariates!$A$3:$H$1126,6,false) | L39: =VLOOKUP($A39,covariates!$A$3:$H$1126,7,false) -> 25.2 | M39: =VLOOKUP($A39,covariates!$A$3:$H$1126,8,false) -> 5.48
A40: 36 | B40: =HYPERLINK("https://github.com/d-wkim/phd/blob/main/data/pdf/horstmann_2022.pdf","Horstmann et al., 2022") -> Horstmann et al., 2022 | C40: 36 | D40: HT | E40: ikdc_subjective | F40: continuous | G40: 26 | H40: 83.7 | I40: 12.7 | J40: =VLOOKUP($A40,covariates!$A$3:$H$1126,5,false) -> at surgery | K40: =VLOOKUP($A40,covariates!$A$3:$H$1126,6,false) | L40: =VLOOKUP($A40,covariates!$A$3:$H$1126,7,false) -> 32.7 | M40: =VLOOKUP($A40,covariates!$A$3:$H$1126,8,false) -> 11.4
...

Sheet Sheet44
A2: 1 | B2: Ageberg et al., 2009 | C2: 10.1007/s00167-008-0645-4 | D2: ="https://doi.org/"&C2 -> https://doi.org/10.1007/s00167-008-0645-4
A3: 1 | B3: Ageberg et al., 2009 | C3: 10.1007/s00167-008-0645-4 | D3: ="https://doi.org/"&C3 -> https://doi.org/10.1007/s00167-008-0645-4
A4: 2 | B4: Aglietti et al., 2004 | D4: ="https://doi.org/"&C4 -> https://doi.org/
A5: 2 | B5: Aglietti et al., 2004 | D5: ="https://doi.org/"&C5 -> https://doi.org/
A6: 3 | B6: Ahldén et al., 2009 | C6: 10.1007/s00167-009-0846-5 | D6: ="https://doi.org/"&C6 -> https://doi.org/10.1007/s00167-009-0846-5
A7: 3 | B7: Ahldén et al., 2009 | C7: 10.1007/s00167-009-0846-5 | D7: ="https://doi.org/"&C7 -> https://doi.org/10.1007/s00167-009-0846-5
A8: 4 | B8: Anderson et al., 2001 | C8: 10.1177/03635465010290030201 | D8: ="https://doi.org/"&C8 -> https://doi.org/10.1177/03635465010290030201
A9: 4 | B9: Anderson et al., 2001 | C9: 10.1177/03635465010290030201 | D9: ="https://doi.org/"&C9 -> https://doi.org/10.1177/03635465010290030201
A10: 5 | B10: Anz et al., 2023 | C10: 10.1177/23259671231210035 | D10: ="https://doi.org/"&C10 -> https://doi.org/10.1177/23259671231210035
A11: 5 | B11: Anz et al., 2023 | C11: 10.1177/23259671231210035 | D11: ="https://doi.org/"&C11 -> https://doi.org/10.1177/23259671231210035
A12: 6 | B12: Aune et al., 2001 | C12: 10.1177/03635465010290060901 | D12: ="https://doi.org/"&C12 -> https://doi.org/10.1177/03635465010290060901
A13: 6 | B13: Aune et al., 2001 | C13: 10.1177/03635465010290060901 | D13: ="https://doi.org/"&C13 -> https://doi.org/10.1177/03635465010290060901
A14: 7 | B14: Barenius et al., 2010 | C14: 10.1177/0363546510369549 | D14: ="https://doi.org/"&C14 -> https://doi.org/10.1177/0363546510369549
A15: 7 | B15: Barenius et al., 2010 | C15: 10.1177/0363546510369549 | D15: ="https://doi.org/"&C15 -> https://doi.org/10.1177/0363546510369549
A16: 8 | B16: Barié et al., 2020 | C16: 10.1007/s00402-020-03508-1 | D16: ="https://doi.org/"&C16 -> https://doi.org/10.1007/s00402-020-03508-1
A17: 8 | B17: Barié et al., 2020 | C17: 10.1007/s00402-020-03508-1 | D17: ="https://doi.org/"&C17 -> https://doi.org/10.1007/s00402-020-03508-1
... A31: 15 | B31: Ejerhed et al., 2003 | C31: 10.1177/03635465030310011401 | D31: ="https://doi.org/"&C31 -> https://doi.org/10.1177/03635465030310011401
A32: 16 | B32: Eriksson et al., 2001 | D32: ="https://doi.org/"&C32 -> https://doi.org/
A33: 16 | B33: Eriksson et al., 2001 | D33: ="https://doi.org/"&C33 -> https://doi.org/
A34: 17 | B34: Feller & Webster, 2003 | C34: 10.1177/03635465030310041501 | D34: ="https://doi.org/"&C34 -> https://doi.org/10.1177/03635465030310041501
A35: 17 | B35: Feller & Webster, 2003 | C35: 10.1177/03635465030310041501 | D35: ="https://doi.org/"&C35 -> https://doi.org/10.1177/03635465030310041501
A36: 18 | B36: Gifstad et al., 2013 | C36: 10.1007/s00167-012-1947-0 | D36: ="https://doi.org/"&C36 -> https://doi.org/10.1007/s00167-012-1947-0
A37: 18 | B37: Gifstad et al., 2013 | C37: 10.1007/s00167-012-1947-0 | D37: ="https://doi.org/"&C37 -> https://doi.org/10.1007/s00167-012-1947-0
A38: 19 | B38: Guglielmetti et al., 2021 | C38: 10.1177/23259671211028168 | D38: ="https://doi.org/"&C38 -> https://doi.org/10.1177/23259671211028168
A39: 19 | B39: Guglielmetti et al., 2021 | C39: 10.1177/23259671211028168 | D39: ="https://doi.org/"&C39 -> https://doi.org/10.1177/23259671211028168
A40: 20 | B40: Harilainen et al., 2006 | C40: 10.1007/s00167-006-0059-0 | D40: ="https://doi.org/"&C40 -> https://doi.org/10.1007/s00167-006-0059-0
A41: 20 | B41: Harilainen et al., 2006 | C41: 10.1007/s00167-006-0059-0 | D41: ="https://doi.org/"&C41 -> https://doi.org/10.1007/s00167-006-0059-0
A42: 21 | B42: Heijne & Werner, 2010 | C42: 10.1007/s00167-009-0961-3 | D42: ="https://doi.org/"&C42 -> https://doi.org/10.1007/s00167-009-0961-3
A43: 21 | B43: Heijne & Werner, 2010 | C43: 10.1007/s00167-009-0961-3 | D43: ="https://doi.org/"&C43 -> https://doi.org/10.1007/s00167-009-0961-3
A44: 22 | B44: Holm et al., 2010 | C44: 10.1177/0363546509350301 | D44: ="https://doi.org/"&C44 -> https://doi.org/10.1177/0363546509350301
A45: 22 | B45: Holm et al., 2010 | C45: 10.1177/0363546509350301 | D45: ="https://doi.org/"&C45 -> https://doi.org/10.1177/0363546509350301
... A59: 29 | B59: Konrads et al., 2016 | C59: 10.1007/s00402-015-2386-4 | D59: ="https://doi.org/"&C59 -> https://doi.org/10.1007/s00402-015-2386-4
A60: 30 | B60: Laoruengthana et al., 2009 | D60: ="https://doi.org/"&C60 -> https://doi.org/
A61: 30 | B61: Laoruengthana et al., 2009 | D61: ="https://doi.org/"&C61 -> https://doi.org/
A62: 31 | B62: Lawhorn et al., 2012 | C62: 10.1016/j.arthro.2012.05.010 | D62: ="https://doi.org/"&C62 -> https://doi.org/10.1016/j.arthro.2012.05.010
A63: 31 | B63: Lawhorn et al., 2012 | C63: 10.1016/j.arthro.2012.05.010 | D63: ="https://doi.org/"&C63 -> https://doi.org/10.1016/j.arthro.2012.05.010
A64: 32 | B64: Laxdal et al., 2005 | C64: 10.1016/j.arthro.2004.09.014 | D64: ="https://doi.org/"&C64 -> https://doi.org/10.1016/j.arthro.2004.09.014
A65: 32 | B65: Laxdal et al., 2005 | C65: 10.1016/j.arthro.2004.09.014 | D65: ="https://doi.org/"&C65 -> https://doi.org/10.1016/j.arthro.2004.09.014
A66: 33 | B66: Li et al., 2015 | C66: 10.1016/j.arthro.2015.02.033 | D66: ="https://doi.org/"&C66 -> https://doi.org/10.1016/j.arthro.2015.02.033
A67: 33 | B67: Li et al., 2015 | C67: 10.1016/j.arthro.2015.02.033 | D67: ="https://doi.org/"&C67 -> https://doi.org/10.1016/j.arthro.2015.02.033
...

Sheet outcomes
A1: id | B1: study | C1: subgroup | D1: outcome | E1: data_type | F1: ni | G1: yi | H1: sdi | I1: min | J1: q1 | K1: median | L1: q3 | M1: max | N1: TE | O1: mean | P1: sd | Q1: min | R1: q1 | S1: median | T1: q3 | U1: max | V1: seTE | W1: male | X1: female | Y1: vi | Z1: mean | AA1: sd | AB1: min | AC1: q1 | AD1: median | AE1: q3 | AF1: max | AG1: screening | AH1: age_mean | AI1: age_sd | AJ1: male | AK1: female | AL1: follow-up_mo | AM1: follow-up_yr
A2: 6 | B2: =HYPERLINK("https://github.com/d-wkim/phd/blob/main/data/pdf/anz_2023.pdf","Anz et al., 2023") -> Anz et al., 2023 | C2: BPTB | D2: graft rupture | E2: dichotomous | F2: 8 | G2: 0 | H2: =iferror(P_SD(F2,G2),"") -> 0.1767767 | AG2: Included | AH2: =iferror(VLOOKUP($B2,covariates!$B$3:$Z$1126,6,FALSE),"") -> 29.4 | AI2: =iferror(VLOOKUP($B2,covariates!$B$3:$Z$1126,7,FALSE),"") -> 7.343 | AJ2: =iferror(VLOOKUP($B2,covariates!$B$3:$Z$1126,14,FALSE),"") -> 4 | AK2: =iferror(VLOOKUP($B2,covariates!$B$3:$Z$1126,16,FALSE),"") -> 6 | AL2: =iferror(VLOOKUP($B2,covariates!$B$3:$Z$1126,18,FALSE),"") -> 12 | AM2: =iferror(VLOOKUP($B2,covariates!$B$3:$Z$1126,19,FALSE),"") -> 1
A3: 6 | B3: =HYPERLINK("https://github.com/d-wkim/phd/blob/main/data/pdf/anz_2023.pdf","Anz et al., 2023") -> Anz et al., 2023 | C3: HT | D3: graft rupture | E3: dichotomous | F3: 8 | G3: 0 | H3: =iferror(P_SD(F3,G3),"") -> 0.1767767 | AG3: Included | AH3: =iferror(VLOOKUP($B3,covariates!$B$3:$Z$1126,6,FALSE),"") -> 29.4 | AI3: =iferror(VLOOKUP($B3,covariates!$B$3:$Z$1126,7,FALSE),"") -> 7.343 | AJ3: =iferror(VLOOKUP($B3,covariates!$B$3:$Z$1126,14,FALSE),"") -> 4 | AK3: =iferror(VLOOKUP($B3,covariates!$B$3:$Z$1126,16,FALSE),"") -> 6 | AL3: =iferror(VLOOKUP($B3,covariates!$B$3:$Z$1126,18,FALSE),"") -> 12 | AM3: =iferror(VLOOKUP($B3,covariates!$B$3:$Z$1126,19,FALSE),"") -> 1
A4: 12 | B4: =HYPERLINK("https://github.com/d-wkim/phd/blob/main/data/pdf/bi_2018.pdf","Bi et al., 2018") -> Bi et al., 2018 | C4: HT | D4: graft rupture | E4: dichotomous | H4: =iferror(P_SD(F4,G4),"") | AG4: Excluded | AH4: =iferror(VLOOKUP($B4,covariates!$B$3:$Z$1126,6,FALSE),"") -> 27.9 | AI4: =iferror(VLOOKUP($B4,covariates!$B$3:$Z$1126,7,FALSE),"") -> 6.7 | AJ4: =iferror(VLOOKUP($B4,covariates!$B$3:$Z$1126,14,FALSE),"") -> 31 | AK4: =iferror(VLOOKUP($B4,covariates!$B$3:$Z$1126,16,FALSE),"") -> 31 | AL4: =iferror(VLOOKUP($B4,covariates!$B$3:$Z$1126,18,FALSE),"") -> 30.3 | AM4: =iferror(VLOOKUP($B4,covariates!$B$3:$Z$1126,19,FALSE),"") -> 2.5
A5: 12 | B5: =HYPERLINK("https://github.com/d-wkim/phd/blob/main/data/pdf/bi_2018.pdf","Bi et al., 2018") -> Bi et al., 2018 | C5: PLT | D5: graft rupture | E5: dichotomous | H5: =iferror(P_SD(F5,G5),"") | AG5: Excluded | AH5: =iferror(VLOOKUP($B5,covariates!$B$3:$Z$1126,6,FALSE),"") -> 27.9 | AI5: =iferror(VLOOKUP($B5,covariates!$B$3:$Z$1126,7,FALSE),"") -> 6.7 | AJ5: =iferror(VLOOKUP($B5,covariates!$B$3:$Z$1126,14,FALSE),"") -> 31 | AK5: =iferror(VLOOKUP($B5,covariates!$B$3:$Z$1126,16,FALSE),"") -> 31 | AL5: =iferror(VLOOKUP($B5,covariates!$B$3:$Z$1126,18,FALSE),"") -> 30.3 | AM5: =iferror(VLOOKUP($B5,covariates!$B$3:$Z$1126,19,FALSE),"") -> 2.5
A6: 22 | B6: =HYPERLINK("https://github.com/d-wkim/phd/blob/main/data/pdf/cruz_2022.pdf","Cruz et al., 2022") -> Cruz et al., 2022 | C6: HT | D6: graft rupture | E6: dichotomous | H6: =iferror(P_SD(F6,G6),"") | AG6: Excluded | AH6: =iferror(VLOOKUP($B6,covariates!$B$3:$Z$1126,6,FALSE),"") | AI6: =iferror(VLOOKUP($B6,covariates!$B$3:$Z$1126,7,FALSE),"") | AJ6: =iferror(VLOOKUP($B6,covariates!$B$3:$Z$1126,14,FALSE),"") | AK6: =iferror(VLOOKUP($B6,covariates!$B$3:$Z$1126,16,FALSE),"") | AL6: =iferror(VLOOKUP($B6,covariates!$B$3:$Z$1126,18,FALSE),"") | AM6: =iferror(VLOOKUP($B6,covariates!$B$3:$Z$1126,19,FALSE),"")
A7: 22 | B7: =HYPERLINK("https://github.com/d-wkim/phd/blob/main/data/pdf/cruz_2022.pdf","Cruz et al., 2022") -> Cruz et al., 2022 | C7: TA | D7: graft rupture | E7: dichotomous | H7: =iferror(P_SD(F7,G7),"") | AG7: Excluded | AH7: =iferror(VLOOKUP($B7,covariates!$B$3:$Z$1126,6,FALSE),"") | AI7: =iferror(VLOOKUP($B7,covariates!$B$3:$Z$1126,7,FALSE),"") | AJ7: =iferror(VLOOKUP($B7,covariates!$B$3:$Z$1126,14,FALSE),"") | AK7: =iferror(VLOOKUP($B7,covariates!$B$3:$Z$1126,16,FALSE),"") | AL7: =iferror(VLOOKUP($B7,covariates!$B$3:$Z$1126,18,FALSE),"") | AM7: =iferror(VLOOKUP($B7,covariates!$B$3:$Z$1126,19,FALSE),"")
A8: 43 | B8: =HYPERLINK("https://github.com/d-wkim/phd/blob/main/data/pdf/kautzner_2015.pdf","Kautzner et al., 2015") -> Kautzner et al., 2015 | C8: BPTB | D8: graft rupture | E8: dichotomous | F8: 74 | G8: 0 | H8: =iferror(P_SD(F8,G8),"") -> 0.058123819 | AG8: Included | AH8: =iferror(VLOOKUP($B8,covariates!$B$3:$Z$1126,6,FALSE),"") -> 26 | AI8: =iferror(VLOOKUP($B8,covariates!$B$3:$Z$1126,7,FALSE),"") -> 6.275 | AJ8: =iferror(VLOOKUP($B8,covariates!$B$3:$Z$1126,14,FALSE),"") -> 0 | AK8: =iferror(VLOOKUP($B8,covariates!$B$3:$Z$1126,16,FALSE),"") -> 74 | AL8: =iferror(VLOOKUP($B8,covariates!$B$3:$Z$1126,18,FALSE),"") -> 24 | AM8: =iferror(VLOOKUP($B8,covariates!$B$3:$Z$1126,19,FALSE),"") -> 2
A9: 43 | B9: =HYPERLINK("https://github.com/d-wkim/phd/blob/main/data/pdf/kautzner_2015.pdf","Kautzner et al., 2015") -> Kautzner et al., 2015 | C9: HT | D9: graft rupture | E9: dichotomous | F9: 73 | G9: 2 | H9: =iferror(P_SD(F9,G9),"") -> 0.3008452 | AG9: Included | AH9: =iferror(VLOOKUP($B9,covariates!$B$3:$Z$1126,6,FALSE),"") -> 26 | AI9: =iferror(VLOOKUP($B9,covariates!$B$3:$Z$1126,7,FALSE),"") -> 6.275 | AJ9: =iferror(VLOOKUP($B9,covariates!$B$3:$Z$1126,14,FALSE),"") -> 0 | AK9: =iferror(VLOOKUP($B9,covariates!$B$3:$Z$1126,16,FALSE),"") -> 74 | AL9: =iferror(VLOOKUP($B9,covariates!$B$3:$Z$1126,18,FALSE),"") -> 24 | AM9: =iferror(VLOOKUP($B9,covariates!$B$3:$Z$1126,19,FALSE),"") -> 2
A10: 49 | B10: =HYPERLINK("https://github.com/d-wkim/phd/blob/main/data/pdf/laxdal_2005.pdf","Laxdal et al., 2005") -> Laxdal et al., 2005 | C10: BPTB | D10: graft rupture | E10: dichotomous | F10: 40 | G10: 1 | H10: =iferror(P_SD(F10,G10),"") -> 0.24325213 | AG10: Included | AH10: =iferror(VLOOKUP($B10,covariates!$B$3:$Z$1126,6,FALSE),"") -> 28 | AI10: =iferror(VLOOKUP($B10,covariates!$B$3:$Z$1126,7,FALSE),"") -> 8.347 | AJ10: =iferror(VLOOKUP($B10,covariates!$B$3:$Z$1126,14,FALSE),"") | AK10: =iferror(VLOOKUP($B10,covariates!$B$3:$Z$1126,16,FALSE),"") | AL10: =iferror(VLOOKUP($B10,covariates!$B$3:$Z$1126,18,FALSE),"") -> 26 | AM10: =iferror(VLOOKUP($B10,covariates!$B$3:$Z$1126,19,FALSE),"") -> 2.2
A11: 49 | B11: =HYPERLINK("https://github.com/d-wkim/phd/blob/main/data/pdf/laxdal_2005.pdf","Laxdal et al., 2005") -> Laxdal et al., 2005 | C11: HT | D11: graft rupture | E11: dichotomous | F11: 78 | G11: 2 | H11: 0.42059596 | AG11: Included | AH11: =iferror(VLOOKUP($B11,covariates!$B$3:$Z$1126,6,FALSE),"") -> 28 | AI11: =iferror(VLOOKUP($B11,covariates!$B$3:$Z$1126,7,FALSE),"") -> 8.347 | AJ11: =iferror(VLOOKUP($B11,covariates!$B$3:$Z$1126,14,FALSE),"") | AK11: =iferror(VLOOKUP($B11,covariates!$B$3:$Z$1126,16,FALSE),"") | AL11: =iferror(VLOOKUP($B11,covariates!$B$3:$Z$1126,18,FALSE),"") -> 26 | AM11: =iferror(VLOOKUP($B11,covariates!$B$3:$Z$1126,19,FALSE),"") -> 2.2
A12: 54 | B12: =HYPERLINK("https://github.com/d-wkim/phd/blob/main/data/pdf/lucidi_2025.pdf","Lucidi et al., 2025") -> Lucidi et al., 2025 | C12: BPTB | D12: graft rupture | E12: dichotomous | F12: 19 | G12: 7 | H12: =iferror(P_SD(F12,G12),"") -> 2.7243118 | AG12: Included | AH12: =iferror(VLOOKUP($B12,covariates!$B$3:$Z$1126,6,FALSE),"") -> 52.8 | AI12: =iferror(VLOOKUP($B12,covariates!$B$3:$Z$1126,7,FALSE),"") -> 7.3 | AJ12: =iferror(VLOOKUP($B12,covariates!$B$3:$Z$1126,14,FALSE),"") | AK12: =iferror(VLOOKUP($B12,covariates!$B$3:$Z$1126,16,FALSE),"") | AL12: =iferror(VLOOKUP($B12,covariates!$B$3:$Z$1126,18,FALSE),"") -> 240 | AM12: =iferror(VLOOKUP($B12,covariates!$B$3:$Z$1126,19,FALSE),"") -> 20
A13: 54 | B13: =HYPERLINK("https://github.com/d-wkim/phd/blob/main/data/pdf/lucidi_2025.pdf","Lucidi et al., 2025") -> Lucidi et al., 2025 | C13: HT | D13: graft rupture | E13: dichotomous | F13: 20 | G13: 3 | H13: =iferror(P_SD(F13,G13),"") -> 0.92073387 | AG13: Included | AH13: =iferror(VLOOKUP($B13,covariates!$B$3:$Z$1126,6,FALSE),"") -> 52.8 | AI13: =iferror(VLOOKUP($B13,covariates!$B$3:$Z$1126,7,FALSE),"") -> 7.3 | AJ13: =iferror(VLOOKUP($B13,covariates!$B$3:$Z$1126,14,FALSE),"") | AK13: =iferror(VLOOKUP($B13,covariates!$B$3:$Z$1126,16,FALSE),"") | AL13: =iferror(VLOOKUP($B13,covariates!$B$3:$Z$1126,18,FALSE),"") -> 240 | AM13: =iferror(VLOOKUP($B13,covariates!$B$3:$Z$1126,19,FALSE),"") -> 20
A14: 66 | B14: =HYPERLINK("https://github.com/d-wkim/phd/blob/main/data/pdf/mohtadi_2016a.pdf","Mohtadi et al., 2016") -> Mohtadi et al., 2016 | C14: BPTB | D14: graft rupture | E14: dichotomous | F14: 110 | G14: 19 | H14: =iferror(P_SD(F14,G14),"") -> 2.2474475 | AG14: Included | AH14: =iferror(VLOOKUP($B14,covariates!$B$3:$Z$1126,6,FALSE),"") -> 28.7 | AI14: =iferror(VLOOKUP($B14,covariates!$B$3:$Z$1126,7,FALSE),"") -> 9.9 | AJ14: =iferror(VLOOKUP($B14,covariates!$B$3:$Z$1126,14,FALSE),"") -> 63 | AK14: =iferror(VLOOKUP($B14,covariates!$B$3:$Z$1126,16,FALSE),"") -> 47 | AL14: =iferror(VLOOKUP($B14,covariates!$B$3:$Z$1126,18,FALSE),"") -> 24 | AM14: =iferror(VLOOKUP($B14,covariates!$B$3:$Z$1126,19,FALSE),"") -> 2
A15: 66 | B15: =HYPERLINK("https://github.com/d-wkim/phd/blob/main/data/pdf/mohtadi_2016a.pdf","Mohtadi et al., 2016") -> Mohtadi et al., 2016 | C15: HT | D15: graft rupture | E15: dichotomous | F15: 110 | G15: 24 | H15: =iferror(P_SD(F15,G15),"") -> 2.9878857 | AG15: Included | AH15: =iferror(VLOOKUP($B15,covariates!$B$3:$Z$1126,6,FALSE),"") -> 28.7 | AI15: =iferror(VLOOKUP($B15,covariates!$B$3:$Z$1126,7,FALSE),"") -> 9.9 | AJ15: =iferror(VLOOKUP($B15,covariates!$B$3:$Z$1126,14,FALSE),"") -> 63 | AK15: =iferror(VLOOKUP($B15,covariates!$B$3:$Z$1126,16,FALSE),"") -> 47 | AL15: =iferror(VLOOKUP($B15,covariates!$B$3:$Z$1126,18,FALSE),"") -> 24 | AM15: =iferror(VLOOKUP($B15,covariates!$B$3:$Z$1126,19,FALSE),"") -> 2
A16: 67 | B16: =HYPERLINK("https://github.com/d-wkim/phd/blob/main/data/pdf/mohtadi_chan_2019.pdf","Mohtadi & Chan, 2019") -> Mohtadi & Chan, 2019 | C16: BPTB | D16: graft rupture | E16: dichotomous | H16: =iferror(P_SD(F16,G16),"") | AG16: Excluded | AH16: =iferror(VLOOKUP($B16,covariates!$B$3:$Z$1126,6,FALSE),"") | AI16: =iferror(VLOOKUP($B16,covariates!$B$3:$Z$1126,7,FALSE),"") | AJ16: =iferror(VLOOKUP($B16,covariates!$B$3:$Z$1126,14,FALSE),"") | AK16: =iferror(VLOOKUP($B16,covariates!$B$3:$Z$1126,16,FALSE),"") | AL16: =iferror(VLOOKUP($B16,covariates!$B$3:$Z$1126,18,FALSE),"") | AM16: =iferror(VLOOKUP($B16,covariates!$B$3:$Z$1126,19,FALSE),"")
A17: 67 | B17: =HYPERLINK("https://github.com/d-wkim/phd/blob/main/data/pdf/mohtadi_chan_2019.pdf","Mohtadi & Chan, 2019") -> Mohtadi & Chan, 2019 | C17: HT | D17: graft rupture | E17: dichotomous | H17: =iferror(P_SD(F17,G17),"") | AG17: Excluded | AH17: =iferror(VLOOKUP($B17,covariates!$B$3:$Z$1126,6,FALSE),"") | AI17: =iferror(VLOOKUP($B17,covariates!$B$3:$Z$1126,7,FALSE),"") | AJ17: =iferror(VLOOKUP($B17,covariates!$B$3:$Z$1126,14,FALSE),"") | AK17: =iferror(VLOOKUP($B17,covariates!$B$3:$Z$1126,16,FALSE),"") | AL17: =iferror(VLOOKUP($B17,covariates!$B$3:$Z$1126,18,FALSE),"") | AM17: =iferror(VLOOKUP($B17,covariates!$B$3:$Z$1126,19,FALSE),"")
A18: 68 | B18: =HYPERLINK("https://github.com/d-wkim/phd/blob/main/data/pdf/moraiti_2010.pdf","Moraiti et al., 2010") -> Moraiti et al., 2010 | C18: BPTB | D18: graft rupture | E18: dichotomous | H18: =iferror(P_SD(F18,G18),"") | AG18: Excluded | AH18: =iferror(VLOOKUP($B18,covariates!$B$3:$Z$1126,6,FALSE),"") -> 23 | AI18: =iferror(VLOOKUP($B18,covariates!$B$3:$Z$1126,7,FALSE),"") -> 2 | AJ18: =iferror(VLOOKUP($B18,covariates!$B$3:$Z$1126,14,FALSE),"") -> 6 | AK18: =iferror(VLOOKUP($B18,covariates!$B$3:$Z$1126,16,FALSE),"") -> 0 | AL18: =iferror(VLOOKUP($B18,covariates!$B$3:$Z$1126,18,FALSE),"") -> 21 | AM18: =iferror(VLOOKUP($B18,covariates!$B$3:$Z$1126,19,FALSE),"") -> 1.8
A19: 68 | B19: =HYPERLINK("https://github.com/d-wkim/phd/blob/main/data/pdf/moraiti_2010.pdf","Moraiti et al., 2010") -> Moraiti et al., 2010 | C19: HT | D19: graft rupture | E19: dichotomous | H19: =iferror(P_SD(F19,G19),"") | AG19: Excluded | AH19: =iferror(VLOOKUP($B19,covariates!$B$3:$Z$1126,6,FALSE),"") -> 23 | AI19: =iferror(VLOOKUP($B19,covariates!$B$3:$Z$1126,7,FALSE),"") -> 2 | AJ19: =iferror(VLOOKUP($B19,covariates!$B$3:$Z$1126,14,FALSE),"") -> 6 | AK19: =iferror(VLOOKUP($B19,covariates!$B$3:$Z$1126,16,FALSE),"") -> 0 | AL19: =iferror(VLOOKUP($B19,covariates!$B$3:$Z$1126,18,FALSE),"") -> 21 | AM19: =iferror(VLOOKUP($B19,covariates!$B$3:$Z$1126,19,FALSE),"") -> 1.8
A20: 70 | B20: =HYPERLINK("https://github.com/d-wkim/phd/blob/main/data/pdf/noh_2011.pdf","Noh et al., 2011") -> Noh et al., 2011 | C20: HT | D20: graft rupture | E20: dichotomous | H20: =iferror(P_SD(F20,G20),"") | AG20: Excluded | AH20: =iferror(VLOOKUP($B20,covariates!$B$3:$Z$1126,6,FALSE),"") -> 25.813974 | AI20: =iferror(VLOOKUP($B20,covariates!$B$3:$Z$1126,7,FALSE),"") -> 7.455 | AJ20: =iferror(VLOOKUP($B20,covariates!$B$3:$Z$1126,14,FALSE),"") -> 30 | AK20: =iferror(VLOOKUP($B20,covariates!$B$3:$Z$1126,16,FALSE),"") -> 3 | AL20: =iferror(VLOOKUP($B20,covariates!$B$3:$Z$1126,18,FALSE),"") -> 28.1 | AM20: =iferror(VLOOKUP($B20,covariates!$B$3:$Z$1126,19,FALSE),"") -> 2.3
A21: 70 | B21: =HYPERLINK("https://github.com/d-wkim/phd/blob/main/data/pdf/noh_2011.pdf","Noh et al., 2011") -> Noh et al., 2011 | C21: AT | D21: graft rupture | E21: dichotomous | H21: =iferror(P_SD(F21,G21),"") | AG21: Excluded | AH21: =iferror(VLOOKUP($B21,covariates!$B$3:$Z$1126,6,FALSE),"") -> 25.813974 | AI21: =iferror(VLOOKUP($B21,covariates!$B$3:$Z$1126,7,FALSE),"") -> 7.455 | AJ21: =iferror(VLOOKUP($B21,covariates!$B$3:$Z$1126,14,FALSE),"") -> 30 | AK21: =iferror(VLOOKUP($B21,covariates!$B$3:$Z$1126,16,FALSE),"") -> 3 | AL21: =iferror(VLOOKUP($B21,covariates!$B$3:$Z$1126,18,FALSE),"") -> 28.1 | AM21: =iferror(VLOOKUP($B21,covariates!$B$3:$Z$1126,19,FALSE),"") -> 2.3
A22: 76 | B22: =HYPERLINK("https://github.com/d-wkim/phd/blob/main/data/pdf/pinczewski_2007.pdf","Pinczewski et al., 2007") -> Pinczewski et al., 2007 | C22: BPTB | D22: graft rupture | E22: dichotomous | F22: 90 | G22: 7 | H22: =iferror(P_SD(F22,G22),"") -> 0.85724394 | AG22: Included | AH22: =iferror(VLOOKUP($B22,covariates!$B$3:$Z$1126,6,FALSE),"") -> 25 | AI22: =iferror(VLOOKUP($B22,covariates!$B$3:$Z$1126,7,FALSE),"") -> 5.485 | AJ22: =iferror(VLOOKUP($B22,covariates!$B$3:$Z$1126,14,FALSE),"") -> 48 | AK22: =iferror(VLOOKUP($B22,covariates!$B$3:$Z$1126,16,FALSE),"") -> 42 | AL22: =iferror(VLOOKUP($B22,covariates!$B$3:$Z$1126,18,FALSE),"") -> 120 | AM22: =iferror(VLOOKUP($B22,covariates!$B$3:$Z$1126,19,FALSE),"") -> 10
A23: 76 | B23: =HYPERLINK("https://github.com/d-wkim/phd/blob/main/data/pdf/pinczewski_2007.pdf","Pinczewski et al., 2007") -> Pinczewski et al., 2007 | C23: HT | D23: graft rupture | E23: dichotomous | F23: 90 | G23: 12 | H23: =iferror(P_SD(F23,G23),"") -> 1.5203258 | AG23: Included | AH23: =iferror(VLOOKUP($B23,covariates!$B$3:$Z$1126,6,FALSE),"") -> 25 | AI23: =iferror(VLOOKUP($B23,covariates!$B$3:$Z$1126,7,FALSE),"") -> 5.485 | AJ23: =iferror(VLOOKUP($B23,covariates!$B$3:$Z$1126,14,FALSE),"") -> 48 | AK23: =iferror(VLOOKUP($B23,covariates!$B$3:$Z$1126,16,FALSE),"") -> 42 | AL23: =iferror(VLOOKUP($B23,covariates!$B$3:$Z$1126,18,FALSE),"") -> 120 | AM23: =iferror(VLOOKUP($B23,covariates!$B$3:$Z$1126,19,FALSE),"") -> 10
A24: 77 | B24: =HYPERLINK("https://github.com/d-wkim/phd/blob/main/data/pdf/popovic_2024.pdf","Popovic et al., 2024") -> Popovic et al., 2024 | C24: BPTB | D24: graft rupture | E24: dichotomous | F24: 38 | G24: 3 | H24: =iferror(P_SD(F24,G24),"") -> 0.6164414 | AG24: Included | AH24: =iferror(VLOOKUP($B24,covariates!$B$3:$Z$1126,6,FALSE),"") -> 27 | AI24: =iferror(VLOOKUP($B24,covariates!$B$3:$Z$1126,7,FALSE),"") -> 6.82 | AJ24: =iferror(VLOOKUP($B24,covariates!$B$3:$Z$1126,14,FALSE),"") | AK24: =iferror(VLOOKUP($B24,covariates!$B$3:$Z$1126,16,FALSE),"") | AL24: =iferror(VLOOKUP($B24,covariates!$B$3:$Z$1126,18,FALSE),"") -> 228 | AM24: =iferror(VLOOKUP($B24,covariates!$B$3:$Z$1126,19,FALSE),"") -> 19
A25: 77 | B25: =HYPERLINK("https://github.com/d-wkim/phd/blob/main/data/pdf/popovic_2024.pdf","Popovic et al., 2024") -> Popovic et al., 2024 | C25: HT | D25: graft rupture | E25: dichotomous | F25: 33 | G25: 4 | H25: =iferror(P_SD(F25,G25),"") -> 0.89139765 | AG25: Included | AH25: =iferror(VLOOKUP($B25,covariates!$B$3:$Z$1126,6,FALSE),"") -> 27 | AI25: =iferror(VLOOKUP($B25,covariates!$B$3:$Z$1126,7,FALSE),"") -> 6.82 | AJ25: =iferror(VLOOKUP($B25,covariates!$B$3:$Z$1126,14,FALSE),"") | AK25: =iferror(VLOOKUP($B25,covariates!$B$3:$Z$1126,16,FALSE),"") | AL25: =iferror(VLOOKUP($B25,covariates!$B$3:$Z$1126,18,FALSE),"") -> 228 | AM25: =iferror(VLOOKUP($B25,covariates!$B$3:$Z$1126,19,FALSE),"") -> 19
A26: 85 | B26: =HYPERLINK("https://github.com/d-wkim/phd/blob/main/data/pdf/smith_2020.pdf","Smith et al., 2020") -> Smith et al., 2020 | C26: BPTB | D26: graft rupture | E26: dichotomous | F26: 32 | G26: 0 | H26: =iferror(P_SD(F26,G26),"") -> 0.088388348 | AG26: Included | AH26: =iferror(VLOOKUP($B26,covariates!$B$3:$Z$1126,6,FALSE),"") -> 17.7 | AI26: =iferror(VLOOKUP($B26,covariates!$B$3:$Z$1126,7,FALSE),"") -> 2.4 | AJ26: =iferror(VLOOKUP($B26,covariates!$B$3:$Z$1126,14,FALSE),"") -> 15 | AK26: =iferror(VLOOKUP($B26,covariates!$B$3:$Z$1126,16,FALSE),"") -> 17 | AL26: =iferror(VLOOKUP($B26,covariates!$B$3:$Z$1126,18,FALSE),"") -> 24 | AM26: =iferror(VLOOKUP($B26,covariates!$B$3:$Z$1126,19,FALSE),"") -> 2
A27: 85 | B27: =HYPERLINK("https://github.com/d-wkim/phd/blob/main/data/pdf/smith_2020.pdf","Smith et al., 2020") -> Smith et al., 2020 | C27: HT | D27: graft rupture | E27: dichotomous | F27: 32 | G27: 2 | H27: =iferror(P_SD(F27,G27),"") -> 0.47140452 | AG27: Included | AH27: =iferror(VLOOKUP($B27,covariates!$B$3:$Z$1126,6,FALSE),"") -> 17.7 | AI27: =iferror(VLOOKUP($B27,covariates!$B$3:$Z$1126,7,FALSE),"") -> 2.4 | AJ27: =iferror(VLOOKUP($B27,covariates!$B$3:$Z$1126,14,FALSE),"") -> 15 | AK27: =iferror(VLOOKUP($B27,covariates!$B$3:$Z$1126,16,FALSE),"") -> 17 | AL27: =iferror(VLOOKUP($B27,covariates!$B$3:$Z$1126,18,FALSE),"") -> 24 | AM27: =iferror(VLOOKUP($B27,covariates!$B$3:$Z$1126,19,FALSE),"") -> 2
A28: 87 | B28: =HYPERLINK("https://github.com/d-wkim/phd/blob/main/data/pdf/sonnery-cottet_2026.pdf","Sonnery-cottet et al., 2026") -> Sonnery-cottet et al., 2026 | C28: BPTB | D28: graft rupture | E28: dichotomous | F28: 273 | G28: 12 | H28: =iferror(P_SD(F28,G28),"") -> 0.79131761 | AG28: Included | AH28: =iferror(VLOOKUP($B28,covariates!$B$3:$Z$1126,6,FALSE),"") -> 24.8 | AI28: =iferror(VLOOKUP($B28,covariates!$B$3:$Z$1126,7,FALSE),"") -> 4.4 | AJ28: =iferror(VLOOKUP($B28,covariates!$B$3:$Z$1126,14,FALSE),"") -> 214 | AK28: =iferror(VLOOKUP($B28,covariates!$B$3:$Z$1126,16,FALSE),"") -> 69 | AL28: =iferror(VLOOKUP($B28,covariates!$B$3:$Z$1126,18,FALSE),"") -> 61.5 | AM28: =iferror(VLOOKUP($B28,covariates!$B$3:$Z$1126,19,FALSE),"") -> 5.1
A29: 87 | B29: =HYPERLINK("https://github.com/d-wkim/phd/blob/main/data/pdf/sonnery-cottet_2026.pdf","Sonnery-cottet et al., 2026") -> Sonnery-cottet et al., 2026 | C29: HT | D29: graft rupture | E29: dichotomous | F29: 283 | G29: 12 | H29: =iferror(P_SD(F29,G29),"") -> 0.77595036 | AG29: Included | AH29: =iferror(VLOOKUP($B29,covariates!$B$3:$Z$1126,6,FALSE),"") -> 24.8 | AI29: =iferror(VLOOKUP($B29,covariates!$B$3:$Z$1126,7,FALSE),"") -> 4.4 | AJ29: =iferror(VLOOKUP($B29,covariates!$B$3:$Z$1126,14,FALSE),"") -> 214 | AK29: =iferror(VLOOKUP($B29,covariates!$B$3:$Z$1126,16,FALSE),"") -> 69 | AL29: =iferror(VLOOKUP($B29,covariates!$B$3:$Z$1126,18,FALSE),"") -> 61.5 | AM29: =iferror(VLOOKUP($B29,covariates!$B$3:$Z$1126,19,FALSE),"") -> 5.1
A30: 90 | B30: =HYPERLINK("https://github.com/d-wkim/phd/blob/main/data/pdf/taylor_2009.pdf","Taylor et al., 2009") -> Taylor et al., 2009 | C30: BPTB | D30: graft rupture | E30: dichotomous | F30: 32 | G30: 3 | H30: =iferror(P_SD(F30,G30),"") -> 0.68272379 | AG30: Included | AH30: =iferror(VLOOKUP($B30,covariates!$B$3:$Z$1126,6,FALSE),"") -> 21.7 | AI30: =iferror(VLOOKUP($B30,covariates!$B$3:$Z$1126,7,FALSE),"") -> 4.597 | AJ30: =iferror(VLOOKUP($B30,covariates!$B$3:$Z$1126,14,FALSE),"") -> 25 | AK30: =iferror(VLOOKUP($B30,covariates!$B$3:$Z$1126,16,FALSE),"") -> 7 | AL30: =iferror(VLOOKUP($B30,covariates!$B$3:$Z$1126,18,FALSE),"") -> 32.4 | AM30: =iferror(VLOOKUP($B30,covariates!$B$3:$Z$1126,19,FALSE),"") -> 2.7
A31: 90 | B31: =HYPERLINK("https://github.com/d-wkim/phd/blob/main/data/pdf/taylor_2009.pdf","Taylor et al., 2009") -> Taylor et al., 2009 | C31: HT | D31: graft rupture | E31: dichotomous | F31: 32 | G31: 4 | H31: =iferror(P_SD(F31,G31),"") -> 0.90913729 | AG31: Included | AH31: =iferror(VLOOKUP($B31,covariates!$B$3:$Z$1126,6,FALSE),"") -> 21.7 | AI31: =iferror(VLOOKUP($B31,covariates!$B$3:$Z$1126,7,FALSE),"") -> 4.597 | AJ31: =iferror(VLOOKUP($B31,covariates!$B$3:$Z$1126,14,FALSE),"") -> 25 | AK31: =iferror(VLOOKUP($B31,covariates!$B$3:$Z$1126,16,FALSE),"") -> 7 | AL31: =iferror(VLOOKUP($B31,covariates!$B$3:$Z$1126,18,FALSE),"") -> 32.4 | AM31: =iferror(VLOOKUP($B31,covariates!$B$3:$Z$1126,19,FALSE),"") -> 2.7
A32: 96 | B32: =HYPERLINK("https://github.com/d-wkim/phd/blob/main/data/pdf/wipfler_2011.pdf","Wipfler et al., 2011") -> Wipfler et al., 2011 | C32: BPTB | D32: graft rupture | E32: dichotomous | F32: 29 | G32: 3 | H32: =iferror(P_SD(F32,G32),"") -> 0.72492603 | AG32: Included | AH32: =iferror(VLOOKUP($B32,covariates!$B$3:$Z$1126,6,FALSE),"") -> 29.87 | AI32: =iferror(VLOOKUP($B32,covariates!$B$3:$Z$1126,7,FALSE),"") -> 7.304 | AJ32: =iferror(VLOOKUP($B32,covariates!$B$3:$Z$1126,14,FALSE),"") -> 19 | AK32: =iferror(VLOOKUP($B32,covariates!$B$3:$Z$1126,16,FALSE),"") -> 12 | AL32: =iferror(VLOOKUP($B32,covariates!$B$3:$Z$1126,18,FALSE),"") -> 108 | AM32: =iferror(VLOOKUP($B32,covariates!$B$3:$Z$1126,19,FALSE),"") -> 9
A33: 96 | B33: =HYPERLINK("https://github.com/d-wkim/phd/blob/main/data/pdf/wipfler_2011.pdf","Wipfler et al., 2011") -> Wipfler et al., 2011 | C33: HT | D33: graft rupture | E33: dichotomous | F33: 25 | G33: 3 | H33: =iferror(P_SD(F33,G33),"") -> 0.79545455 | AG33: Included | AH33: =iferror(VLOOKUP($B33,covariates!$B$3:$Z$1126,6,FALSE),"") -> 29.87 | AI33: =iferror(VLOOKUP($B33,covariates!$B$3:$Z$1126,7,FALSE),"") -> 7.304 | AJ33: =iferror(VLOOKUP($B33,covariates!$B$3:$Z$1126,14,FALSE),"") -> 19 | AK33: =iferror(VLOOKUP($B33,covariates!$B$3:$Z$1126,16,FALSE),"") -> 12 | AL33: =iferror(VLOOKUP($B33,covariates!$B$3:$Z$1126,18,FALSE),"") -> 108 | AM33: =iferror(VLOOKUP($B33,covariates!$B$3:$Z$1126,19,FALSE),"") -> 9
A34: 97 | B34: =HYPERLINK("https://github.com/d-wkim/phd/blob/main/data/pdf/yadav_2025.pdf","Yadav et al., 2025") -> Yadav et al., 2025 | C34: HT | D34: graft rupture | E34: dichotomous | F34: 36 | G34: 1 | H34: =iferror(P_SD(F34,G34),"") -> 0.25714286 | AG34: Included | AH34: =iferror(VLOOKUP($B34,covariates!$B$3:$Z$1126,6,FALSE),"") -> 30.06 | AI34: =iferror(VLOOKUP($B34,covariates!$B$3:$Z$1126,7,FALSE),"") -> 8.87 | AJ34: =iferror(VLOOKUP($B34,covariates!$B$3:$Z$1126,14,FALSE),"") -> 32 | AK34: =iferror(VLOOKUP($B34,covariates!$B$3:$Z$1126,16,FALSE),"") -> 4 | AL34: =iferror(VLOOKUP($B34,covariates!$B$3:$Z$1126,18,FALSE),"") -> 12 | AM34: =iferror(VLOOKUP($B34,covariates!$B$3:$Z$1126,19,FALSE),"") -> 1
A35: 97 | B35: =HYPERLINK("https://github.com/d-wkim/phd/blob/main/data/pdf/yadav_2025.pdf","Yadav et al., 2025") -> Yadav et al., 2025 | C35: QT | D35: graft rupture | E35: dichotomous | F35: 33 | G35: 0 | H35: =iferror(P_SD(F35,G35),"") -> 0.087038828 | AG35: Included | AH35: =iferror(VLOOKUP($B35,covariates!$B$3:$Z$1126,6,FALSE),"") -> 30.06 | AI35: =iferror(VLOOKUP($B35,covariates!$B$3:$Z$1126,7,FALSE),"") -> 8.87 | AJ35: =iferror(VLOOKUP($B35,covariates!$B$3:$Z$1126,14,FALSE),"") -> 32 | AK35: =iferror(VLOOKUP($B35,covariates!$B$3:$Z$1126,16,FALSE),"") -> 4 | AL35: =iferror(VLOOKUP($B35,covariates!$B$3:$Z$1126,18,FALSE),"") -> 12 | AM35: =iferror(VLOOKUP($B35,covariates!$B$3:$Z$1126,19,FALSE),"") -> 1
A36: 3 | B36: =HYPERLINK("https://github.com/d-wkim/phd/blob/main/data/pdf/ahldén_2009.pdf","Ahldén et al., 2009") -> Ahldén et al., 2009 | C36: BPTB | D36: ikdc_objective | E36: dichotomous | O36: 26 | AG36: Excluded | AH36: =iferror(VLOOKUP($B36,covariates!$B$3:$Z$1126,6,FALSE),"") -> 27.412608 | AI36: =iferror(VLOOKUP($B36,covariates!$B$3:$Z$1126,7,FALSE),"") -> 8.902 | AJ36: =iferror(VLOOKUP($B36,covariates!$B$3:$Z$1126,14,FALSE),"") -> 14 | AK36: =iferror(VLOOKUP($B36,covariates!$B$3:$Z$1126,16,FALSE),"") -> 8 | AL36: =iferror(VLOOKUP($B36,covariates!$B$3:$Z$1126,18,FALSE),"") -> 90.271348 | AM36: =iferror(VLOOKUP($B36,covariates!$B$3:$Z$1126,19,FALSE),"") -> 7.5
A37: 3 | B37: =HYPERLINK("https://github.com/d-wkim/phd/blob/main/data/pdf/ahldén_2009.pdf","Ahldén et al., 2009") -> Ahldén et al., 2009 | C37: HT | D37: ikdc_objective | E37: dichotomous | O37: 29 | AG37: Excluded | AH37: =iferror(VLOOKUP($B37,covariates!$B$3:$Z$1126,6,FALSE),"") -> 27.412608 | AI37: =iferror(VLOOKUP($B37,covariates!$B$3:$Z$1126,7,FALSE),"") -> 8.902 | AJ37: =iferror(VLOOKUP($B37,covariates!$B$3:$Z$1126,14,FALSE),"") -> 14 | AK37: =iferror(VLOOKUP($B37,covariates!$B$3:$Z$1126,16,FALSE),"") -> 8 | AL37: =iferror(VLOOKUP($B37,covariates!$B$3:$Z$1126,18,FALSE),"") -> 90.271348 | AM37: =iferror(VLOOKUP($B37,covariates!$B$3:$Z$1126,19,FALSE),"") -> 7.5
A38: 5 | B38: =HYPERLINK("https://github.com/d-wkim/phd/blob/main/data/pdf/anderson_2001.pdf","Anderson et al., 2001") -> Anderson et al., 2001 | C38: BPTB | D38: ikdc_objective | E38: dichotomous | AG38: Excluded | AH38: =iferror(VLOOKUP($B38,covariates!$B$3:$Z$1126,6,FALSE),"") -> 23.6 | AI38: =iferror(VLOOKUP($B38,covariates!$B$3:$Z$1126,7,FALSE),"") -> 7.132 | AJ38: =iferror(VLOOKUP($B38,covariates!$B$3:$Z$1126,14,FALSE),"") -> 23 | AK38: =iferror(VLOOKUP($B38,covariates!$B$3:$Z$1126,16,FALSE),"") -> 12 | AL38: =iferror(VLOOKUP($B38,covariates!$B$3:$Z$1126,18,FALSE),"") -> 34.6 | AM38: =iferror(VLOOKUP($B38,covariates!$B$3:$Z$1126,19,FALSE),"") -> 2.9
A39: 5 | B39: =HYPERLINK("https://github.com/d-wkim/phd/blob/main/data/pdf/anderson_2001.pdf","Anderson et al., 2001") -> Anderson et al., 2001 | C39: HT | D39: ikdc_objective | E39: dichotomous | AG39: Excluded | AH39: =iferror(VLOOKUP($B39,covariates!$B$3:$Z$1126,6,FALSE),"") -> 23.6 | AI39: =iferror(VLOOKUP($B39,covariates!$B$3:$Z$1126,7,FALSE),"") -> 7.132 | AJ39: =iferror(VLOOKUP($B39,covariates!$B$3:$Z$1126,14,FALSE),"") -> 23 | AK39: =iferror(VLOOKUP($B39,covariates!$B$3:$Z$1126,16,FALSE),"") -> 12 | AL39: =iferror(VLOOKUP($B39,covariates!$B$3:$Z$1126,18,FALSE),"") -> 34.6 | AM39: =iferror(VLOOKUP($B39,covariates!$B$3:$Z$1126,19,FALSE),"") -> 2.9
A40: 11 | B40: =HYPERLINK("https://github.com/d-wkim/phd/blob/main/data/pdf/beynnon_2002.pdf","Beynnon et al., 2002") -> Beynnon et al., 2002 | C40: BPTB | D40: ikdc_objective | E40: dichotomous | AG40: Excluded | AH40: =iferror(VLOOKUP($B40,covariates!$B$3:$Z$1126,6,FALSE),"") -> 28.5 | AI40: =iferror(VLOOKUP($B40,covariates!$B$3:$Z$1126,7,FALSE),"") -> 6.959 | AJ40: =iferror(VLOOKUP($B40,covariates!$B$3:$Z$1126,14,FALSE),"") -> 18 | AK40: =iferror(VLOOKUP($B40,covariates!$B$3:$Z$1126,16,FALSE),"") -> 10 | AL40: =iferror(VLOOKUP($B40,covariates!$B$3:$Z$1126,18,FALSE),"") -> 36 | AM40: =iferror(VLOOKUP($B40,covariates!$B$3:$Z$1126,19,FALSE),"") -> 3
...

Sheet Sheet42
A1: study | B1: subgroup | C1: n
A2: =HYPERLINK("https://github.com/d-wkim/phd/blob/main/data/pdf/ageberg_2009.pdf","Ageberg et al., 2009") -> Ageberg et al., 2009 | B2: BPTB | C2: 16 | D2: =IFERROR(__xludf.DUMMYFUNCTION("join(""; "",A2:C2)"),"Ageberg et al., 2009; BPTB; 16") -> Ageberg et al., 2009; BPTB; 16 | E2: {=unique(D2:D349)} -> Ageberg et al., 2009; BPTB; 16 | F2: =IFERROR(__xludf.DUMMYFUNCTION("split(E2,"";"",FALSE)"),"Ageberg et al., 2009") -> Ageberg et al., 2009 | G2: =IFERROR(__xludf.DUMMYFUNCTION("""COMPUTED_VALUE""")," BPTB") -> BPTB | H2: =IFERROR(__xludf.DUMMYFUNCTION("""COMPUTED_VALUE"""),16.0) -> 16 | J2: Ageberg et al., 2009 | K2: BPTB | L2: 16
A3: =HYPERLINK("https://github.com/d-wkim/phd/blob/main/data/pdf/ageberg_2009.pdf","Ageberg et al., 2009") -> Ageberg et al., 2009 | B3: HT | C3: 20 | D3: =IFERROR(__xludf.DUMMYFUNCTION("join(""; "",A3:C3)"),"Ageberg et al., 2009; HT; 20") -> Ageberg et al., 2009; HT; 20 | E3: Ageberg et al., 2009; HT; 20 | F3: =IFERROR(__xludf.DUMMYFUNCTION("split(E3,"";"",FALSE)"),"Ageberg et al., 2009") -> Ageberg et al., 2009 | G3: =IFERROR(__xludf.DUMMYFUNCTION("""COMPUTED_VALUE""")," HT") -> HT | H3: =IFERROR(__xludf.DUMMYFUNCTION("""COMPUTED_VALUE"""),20.0) -> 20 | J3: Ageberg et al., 2009 | K3: HT | L3: 20
A4: =HYPERLINK("https://github.com/d-wkim/phd/blob/main/data/pdf/aglietti_2004.pdf","Aglietti et al., 2004") -> Aglietti et al., 2004 | B4: BPTB | C4: 60 | D4: =IFERROR(__xludf.DUMMYFUNCTION("join(""; "",A4:C4)"),"Aglietti et al., 2004; BPTB; 60") -> Aglietti et al., 2004; BPTB; 60 | E4: Aglietti et al., 2004; BPTB; 60 | F4: =IFERROR(__xludf.DUMMYFUNCTION("split(E4,"";"",FALSE)"),"Aglietti et al., 2004") -> Aglietti et al., 2004 | G4: =IFERROR(__xludf.DUMMYFUNCTION("""COMPUTED_VALUE""")," BPTB") -> BPTB | H4: =IFERROR(__xludf.DUMMYFUNCTION("""COMPUTED_VALUE"""),60.0) -> 60 | J4: Aglietti et al., 2004 | K4: BPTB | L4: 60
A5: =HYPERLINK("https://github.com/d-wkim/phd/blob/main/data/pdf/aglietti_2004.pdf","Aglietti et al., 2004") -> Aglietti et al., 2004 | B5: BPTB | C5: 60 | D5: =IFERROR(__xludf.DUMMYFUNCTION("join(""; "",A5:C5)"),"Aglietti et al., 2004; BPTB; 60") -> Aglietti et al., 2004; BPTB; 60 | E5: Aglietti et al., 2004; HT; 60 | F5: =IFERROR(__xludf.DUMMYFUNCTION("split(E5,"";"",FALSE)"),"Aglietti et al., 2004") -> Aglietti et al., 2004 | G5: =IFERROR(__xludf.DUMMYFUNCTION("""COMPUTED_VALUE""")," HT") -> HT | H5: =IFERROR(__xludf.DUMMYFUNCTION("""COMPUTED_VALUE"""),60.0) -> 60 | J5: Aglietti et al., 2004 | K5: HT | L5: 60
A6: =HYPERLINK("https://github.com/d-wkim/phd/blob/main/data/pdf/aglietti_2004.pdf","Aglietti et al., 2004") -> Aglietti et al., 2004 | B6: BPTB | C6: 60 | D6: =IFERROR(__xludf.DUMMYFUNCTION("join(""; "",A6:C6)"),"Aglietti et al., 2004; BPTB; 60") -> Aglietti et al., 2004; BPTB; 60 | E6: Ahldén et al., 2009; BPTB; 25 | F6: =IFERROR(__xludf.DUMMYFUNCTION("split(E6,"";"",FALSE)"),"Ahldén et al., 2009") -> Ahldén et al., 2009 | G6: =IFERROR(__xludf.DUMMYFUNCTION("""COMPUTED_VALUE""")," BPTB") -> BPTB | H6: =IFERROR(__xludf.DUMMYFUNCTION("""COMPUTED_VALUE"""),25.0) -> 25 | J6: Ahldén et al., 2009 | K6: BPTB | L6: 25
A7: =HYPERLINK("https://github.com/d-wkim/phd/blob/main/data/pdf/aglietti_2004.pdf","Aglietti et al., 2004") -> Aglietti et al., 2004 | B7: HT | C7: 60 | D7: =IFERROR(__xludf.DUMMYFUNCTION("join(""; "",A7:C7)"),"Aglietti et al., 2004; HT; 60") -> Aglietti et al., 2004; HT; 60 | E7: Ahldén et al., 2009; HT; 22 | F7: =IFERROR(__xludf.DUMMYFUNCTION("split(E7,"";"",FALSE)"),"Ahldén et al., 2009") -> Ahldén et al., 2009 | G7: =IFERROR(__xludf.DUMMYFUNCTION("""COMPUTED_VALUE""")," HT") -> HT | H7: =IFERROR(__xludf.DUMMYFUNCTION("""COMPUTED_VALUE"""),22.0) -> 22 | J7: Ahldén et al., 2009 | K7: HT | L7: 22
A8: =HYPERLINK("https://github.com/d-wkim/phd/blob/main/data/pdf/aglietti_2004.pdf","Aglietti et al., 2004") -> Aglietti et al., 2004 | B8: HT | C8: 60 | D8: =IFERROR(__xludf.DUMMYFUNCTION("join(""; "",A8:C8)"),"Aglietti et al., 2004; HT; 60") -> Aglietti et al., 2004; HT; 60 | E8: Anderson et al., 2001; BPTB; 35 | F8: =IFERROR(__xludf.DUMMYFUNCTION("split(E8,"";"",FALSE)"),"Anderson et al., 2001") -> Anderson et al., 2001 | G8: =IFERROR(__xludf.DUMMYFUNCTION("""COMPUTED_VALUE""")," BPTB") -> BPTB | H8: =IFERROR(__xludf.DUMMYFUNCTION("""COMPUTED_VALUE"""),35.0) -> 35 | J8: Anderson et al., 2001 | K8: BPTB | L8: 35
A9: =HYPERLINK("https://github.com/d-wkim/phd/blob/main/data/pdf/aglietti_2004.pdf","Aglietti et al., 2004") -> Aglietti et al., 2004 | B9: HT | C9: 60 | D9: =IFERROR(__xludf.DUMMYFUNCTION("join(""; "",A9:C9)"),"Aglietti et al., 2004; HT; 60") -> Aglietti et al., 2004; HT; 60 | E9: Anderson et al., 2001; HT; 33 | F9: =IFERROR(__xludf.DUMMYFUNCTION("split(E9,"";"",FALSE)"),"Anderson et al., 2001") -> Anderson et al., 2001 | G9: =IFERROR(__xludf.DUMMYFUNCTION("""COMPUTED_VALUE""")," HT") -> HT | H9: =IFERROR(__xludf.DUMMYFUNCTION("""COMPUTED_VALUE"""),33.0) -> 33 | J9: Anderson et al., 2001 | K9: HT | L9: 33
A10: =HYPERLINK("https://github.com/d-wkim/phd/blob/main/data/pdf/ahldén_2009.pdf","Ahldén et al., 2009") -> Ahldén et al., 2009 | B10: BPTB | C10: 25 | D10: =IFERROR(__xludf.DUMMYFUNCTION("join(""; "",A10:C10)"),"Ahldén et al., 2009; BPTB; 25") -> Ahldén et al., 2009; BPTB; 25 | E10: Anz et al., 2023; BPTB; 16 | F10: =IFERROR(__xludf.DUMMYFUNCTION("split(E10,"";"",FALSE)"),"Anz et al., 2023") -> Anz et al., 2023 | G10: =IFERROR(__xludf.DUMMYFUNCTION("""COMPUTED_VALUE""")," BPTB") -> BPTB | H10: =IFERROR(__xludf.DUMMYFUNCTION("""COMPUTED_VALUE"""),16.0) -> 16 | J10: Anz et al., 2023 | K10: BPTB | L10: 16
A11: =HYPERLINK("https://github.com/d-wkim/phd/blob/main/data/pdf/ahldén_2009.pdf","Ahldén et al., 2009") -> Ahldén et al., 2009 | B11: BPTB | C11: 25 | D11: =IFERROR(__xludf.DUMMYFUNCTION("join(""; "",A11:C11)"),"Ahldén et al., 2009; BPTB; 25") -> Ahldén et al., 2009; BPTB; 25 | E11: Anz et al., 2023; HT; 16 | F11: =IFERROR(__xludf.DUMMYFUNCTION("split(E11,"";"",FALSE)"),"Anz et al., 2023") -> Anz et al., 2023 | G11: =IFERROR(__xludf.DUMMYFUNCTION("""COMPUTED_VALUE""")," HT") -> HT | H11: =IFERROR(__xludf.DUMMYFUNCTION("""COMPUTED_VALUE"""),16.0) -> 16 | J11: Anz et al., 2023 | K11: HT | L11: 16
A12: =HYPERLINK("https://github.com/d-wkim/phd/blob/main/data/pdf/ahldén_2009.pdf","Ahldén et al., 2009") -> Ahldén et al., 2009 | B12: BPTB | C12: 25 | D12: =IFERROR(__xludf.DUMMYFUNCTION("join(""; "",A12:C12)"),"Ahldén et al., 2009; BPTB; 25") -> Ahldén et al., 2009; BPTB; 25 | E12: Aune et al., 2001; BPTB; 32 | F12: =IFERROR(__xludf.DUMMYFUNCTION("split(E12,"";"",FALSE)"),"Aune et al., 2001") -> Aune et al., 2001 | G12: =IFERROR(__xludf.DUMMYFUNCTION("""COMPUTED_VALUE""")," BPTB") -> BPTB | H12: =IFERROR(__xludf.DUMMYFUNCTION("""COMPUTED_VALUE"""),32.0) -> 32 | J12: Aune et al., 2001 | K12: BPTB | L12: 32
