Workbook

Sheet Sheet1
B1: id | C1: study | D1: subgroup | E1: outcome | F1: ni | G1: TE | H1: seTE
A2: 434 | B2: 1 | C2: Ageberg et al., 2009 | D2: BPTB | E2: tegner | F2: 16 | G2: 4.17 | H2: 1.41 | I2: =H2/(SQRT(F2))*1.96 -> 0.6909 | J2: =G2-I2 -> 3.4791 | K2: =G2+I2 -> 4.8609 | L2: =TEXT(I2,"#0.00") -> 0.69 | M2: =TEXT(J2,"#0.00") -> 3.48 | N2: =TEXT(G2,"#0.00")&" ["&L2&", "&M2&"]" -> 4.17 [0.69, 3.48]
A3: 435 | B3: 1 | C3: Ageberg et al., 2009 | D3: HT | E3: tegner | F3: 20 | G3: 3.15 | H3: 1.34 | I3: =H3/(SQRT(F3))*1.96 -> 0.58728089 | J3: =G3-I3 -> 2.5627191 | K3: =G3+I3 -> 3.7372809 | L3: =TEXT(I3,"#0.00") -> 0.59 | M3: =TEXT(J3,"#0.00") -> 2.56 | N3: =TEXT(G3,"#0.00")&" ["&L3&", "&M3&"]" -> 3.15 [0.59, 2.56]
A4: 0 | B4: 1 | C4: Ageberg et al., 2009 | D4: BPTB vs. HT | E4: tegner | F4: 36 | G4: 0.744 | H4: 0.347 | I4: =H4*1.96 -> 0.68012 | J4: =G4-I4 -> 0.06388 | K4: =G4+I4 -> 1.42412 | L4: =TEXT(I4,"#0.00") -> 0.68 | M4: =TEXT(J4,"#0.00") -> 0.06 | N4: =TEXT(G4,"#0.00")&" ["&L4&", "&M4&"]" -> 0.74 [0.68, 0.06]
A5: 124 | B5: 2 | C5: Aglietti et al., 2004 | D5: BPTB | E5: instrumented_laxity | F5: 60 | G5: 2.2 | H5: 1.08 | I5: =H5/(SQRT(F5))*1.96 -> 0.2732777 | J5: =G5-I5 -> 1.9267223 | K5: =G5+I5 -> 2.4732777 | L5: =TEXT(I5,"#0.00") -> 0.27 | M5: =TEXT(J5,"#0.00") -> 1.93 | N5: =TEXT(G5,"#0.00")&" ["&L5&", "&M5&"]" -> 2.20 [0.27, 1.93]
A6: 125 | B6: 2 | C6: Aglietti et al., 2004 | D6: HT | E6: instrumented_laxity | F6: 60 | G6: 1.95 | H6: 1.3 | I6: =H6/(SQRT(F6))*1.96 -> 0.32894539 | J6: =G6-I6 -> 1.6210546 | K6: =G6+I6 -> 2.2789454 | L6: =TEXT(I6,"#0.00") -> 0.33 | M6: =TEXT(J6,"#0.00") -> 1.62 | N6: =TEXT(G6,"#0.00")&" ["&L6&", "&M6&"]" -> 1.95 [0.33, 1.62]
A7: 0 | B7: 2 | C7: Aglietti et al., 2004 | D7: BPTB vs. HT | E7: instrumented_laxity | F7: 120 | G7: 0.209 | H7: 0.183 | I7: =H7*1.96 -> 0.35868 | J7: =G7-I7 -> -0.14968 | K7: =G7+I7 -> 0.56768 | L7: =TEXT(I7,"#0.00") -> 0.36 | M7: =TEXT(J7,"#0.00") -> -0.15 | N7: =TEXT(G7,"#0.00")&" ["&L7&", "&M7&"]" -> 0.21 [0.36, -0.15]
A8: 234 | B8: 2 | C8: Aglietti et al., 2004 | D8: BPTB | E8: lachman_1 | F8: 60 | G8: 0 | H8: 0.06 | I8: =H8/(SQRT(F8))*1.96 -> 0.015182095 | J8: =G8-I8 -> -0.015182095 | K8: =G8+I8 -> 0.015182095 | L8: =TEXT(I8,"#0.00") -> 0.02 | M8: =TEXT(J8,"#0.00") -> -0.02 | N8: =TEXT(G8,"#0.00")&" ["&L8&", "&M8&"]" -> 0.00 [0.02, -0.02]
A9: 235 | B9: 2 | C9: Aglietti et al., 2004 | D9: HT | E9: lachman_1 | F9: 60 | G9: 0 | H9: 0.06 | I9: =H9/(SQRT(F9))*1.96 -> 0.015182095 | J9: =G9-I9 -> -0.015182095 | K9: =G9+I9 -> 0.015182095 | L9: =TEXT(I9,"#0.00") -> 0.02 | M9: =TEXT(J9,"#0.00") -> -0.02 | N9: =TEXT(G9,"#0.00")&" ["&L9&", "&M9&"]" -> 0.00 [0.02, -0.02]
A10: 0 | B10: 2 | C10: Aglietti et al., 2004 | D10: BPTB vs. HT | E10: lachman_1 | F10: 121 | G10: 1 | H10: 2.008316 | I10: =H10*1.96 -> 3.9362994 | J10: =G10-I10 -> -2.9362994 | K10: =G10+I10 -> 4.9362994 | L10: =TEXT(I10,"#0.00") -> 3.94 | M10: =TEXT(J10,"#0.00") -> -2.94 | N10: =TEXT(G10,"#0.00")&" ["&L10&", "&M10&"]" -> 1.00 [3.94, -2.94]
A11: 492 | B11: 2 | C11: Aglietti et al., 2004 | D11: BPTB | E11: lachman_2 | F11: 60 | G11: 0 | H11: 0.06 | I11: =H11/(SQRT(F11))*1.96 -> 0.015182095 | J11: =G11-I11 -> -0.015182095 | K11: =G11+I11 -> 0.015182095 | L11: =TEXT(I11,"#0.00") -> 0.02 | M11: =TEXT(J11,"#0.00") -> -0.02 | N11: =TEXT(G11,"#0.00")&" ["&L11&", "&M11&"]" -> 0.00 [0.02, -0.02]
A12: 493 | B12: 2 | C12: Aglietti et al., 2004 | D12: HT | E12: lachman_2 | F12: 60 | G12: 0 | H12: 0.06 | I12: =H12/(SQRT(F12))*1.96 -> 0.015182095 | J12: =G12-I12 -> -0.015182095 | K12: =G12+I12 -> 0.015182095 | L12: =TEXT(I12,"#0.00") -> 0.02 | M12: =TEXT(J12,"#0.00") -> -0.02 | N12: =TEXT(G12,"#0.00")&" ["&L12&", "&M12&"]" -> 0.00 [0.02, -0.02]
A13: 0 | B13: 2 | C13: Aglietti et al., 2004 | D13: BPTB vs. HT | E13: lachman_2 | F13: 121 | G13: 1 | H13: 2.008316 | I13: =H13*1.96 -> 3.9362994 | J13: =G13-I13 -> -2.9362994 | K13: =G13+I13 -> 4.9362994 | L13: =TEXT(I13,"#0.00") -> 3.94 | M13: =TEXT(J13,"#0.00") -> -2.94 | N13: =TEXT(G13,"#0.00")&" ["&L13&", "&M13&"]" -> 1.00 [3.94, -2.94]
A14: 370 | B14: 2 | C14: Aglietti et al., 2004 | D14: BPTB | E14: pivot_shift_1 | F14: 60 | G14: 10 | H14: 0.07 | I14: =H14/(SQRT(F14))*1.96 -> 0.017712444 | J14: =G14-I14 -> 9.9822876 | K14: =G14+I14 -> 10.017712 | L14: =TEXT(I14,"#0.00") -> 0.02 | M14: =TEXT(J14,"#0.00") -> 9.98 | N14: =TEXT(G14,"#0.00")&" ["&L14&", "&M14&"]" -> 10.00 [0.02, 9.98]
A15: 371 | B15: 2 | C15: Aglietti et al., 2004 | D15: HT | E15: pivot_shift_1 | F15: 60 | G15: 11 | H15: 0.07 | I15: =H15/(SQRT(F15))*1.96 -> 0.017712444 | J15: =G15-I15 -> 10.982288 | K15: =G15+I15 -> 11.017712 | L15: =TEXT(I15,"#0.00") -> 0.02 | M15: =TEXT(J15,"#0.00") -> 10.98 | N15: =TEXT(G15,"#0.00")&" ["&L15&", "&M15&"]" -> 11.00 [0.02, 10.98]
A16: 0 | B16: 2 | C16: Aglietti et al., 2004 | D16: BPTB vs. HT | E16: pivot_shift_1 | F16: 121 | G16: 0.895 | H16: 0.47180799 | I16: =H16*1.96 -> 0.92474366 | J16: =G16-I16 -> -0.029743662 | K16: =G16+I16 -> 1.8197437 | L16: =TEXT(I16,"#0.00") -> 0.92 | M16: =TEXT(J16,"#0.00") -> -0.03 | N16: =TEXT(G16,"#0.00")&" ["&L16&", "&M16&"]" -> 0.90 [0.92, -0.03]
A17: 548 | B17: 2 | C17: Aglietti et al., 2004 | D17: BPTB | E17: pivot_shift_2 | F17: 60 | G17: 0 | H17: 0.07 | I17: =H17/(SQRT(F17))*1.96 -> 0.017712444 | J17: =G17-I17 -> -0.017712444 | K17: =G17+I17 -> 0.017712444 | L17: =TEXT(I17,"#0.00") -> 0.02 | M17: =TEXT(J17,"#0.00") -> -0.02 | N17: =TEXT(G17,"#0.00")&" ["&L17&", "&M17&"]" -> 0.00 [0.02, -0.02]
A18: 549 | B18: 2 | C18: Aglietti et al., 2004 | D18: HT | E18: pivot_shift_2 | F18: 60 | G18: 0 | H18: 0.07 | I18: =H18/(SQRT(F18))*1.96 -> 0.017712444 | J18: =G18-I18 -> -0.017712444 | K18: =G18+I18 -> 0.017712444 | L18: =TEXT(I18,"#0.00") -> 0.02 | M18: =TEXT(J18,"#0.00") -> -0.02 | N18: =TEXT(G18,"#0.00")&" ["&L18&", "&M18&"]" -> 0.00 [0.02, -0.02]
A19: 0 | B19: 2 | C19: Aglietti et al., 2004 | D19: BPTB vs. HT | E19: pivot_shift_2 | F19: 121 | G19: 1 | H19: 2.008316 | I19: =H19*1.96 -> 3.9362994 | J19: =G19-I19 -> -2.9362994 | K19: =G19+I19 -> 4.9362994 | L19: =TEXT(I19,"#0.00") -> 3.94 | M19: =TEXT(J19,"#0.00") -> -2.94 | N19: =TEXT(G19,"#0.00")&" ["&L19&", "&M19&"]" -> 1.00 [3.94, -2.94]
A20: 126 | B20: 3 | C20: Ahldén et al., 2009 | D20: BPTB | E20: instrumented_laxity | F20: 25 | G20: 2.6 | H20: 3.3 | I20: =H20/(SQRT(F20))*1.96 -> 1.2936 | J20: =G20-I20 -> 1.3064 | K20: =G20+I20 -> 3.8936 | L20: =TEXT(I20,"#0.00") -> 1.29 | M20: =TEXT(J20,"#0.00") -> 1.31 | N20: =TEXT(G20,"#0.00")&" ["&L20&", "&M20&"]" -> 2.60 [1.29, 1.31]
A21: 127 | B21: 3 | C21: Ahldén et al., 2009 | D21: HT | E21: instrumented_laxity | F21: 22 | G21: 1.4 | H21: 2.6 | I21: =H21/(SQRT(F21))*1.96 -> 1.0864709 | J21: =G21-I21 -> 0.31352915 | K21: =G21+I21 -> 2.4864709 | L21: =TEXT(I21,"#0.00") -> 1.09 | M21: =TEXT(J21,"#0.00") -> 0.31 | N21: =TEXT(G21,"#0.00")&" ["&L21&", "&M21&"]" -> 1.40 [1.09, 0.31]
A22: 1 | B22: 3 | C22: Ahldén et al., 2009 | D22: BPTB vs. HT | E22: instrumented_laxity | F22: 47 | G22: 0.401 | H22: 0.295 | I22: =H22*1.96 -> 0.5782 | J22: =G22-I22 -> -0.1772 | K22: =G22+I22 -> 0.9792 | L22: =TEXT(I22,"#0.00") -> 0.58 | M22: =TEXT(J22,"#0.00") -> -0.18 | N22: =TEXT(G22,"#0.00")&" ["&L22&", "&M22&"]" -> 0.40 [0.58, -0.18]
A23: 290 | B23: 3 | C23: Ahldén et al., 2009 | D23: BPTB | E23: lysholm | F23: 25 | G23: 80.7 | H23: 21.64 | I23: =H23/(SQRT(F23))*1.96 -> 8.48288 | J23: =G23-I23 -> 72.21712 | K23: =G23+I23 -> 89.18288 | L23: =TEXT(I23,"#0.00") -> 8.48 | M23: =TEXT(J23,"#0.00") -> 72.22 | N23: =TEXT(G23,"#0.00")&" ["&L23&", "&M23&"]" -> 80.70 [8.48, 72.22]
A24: 291 | B24: 3 | C24: Ahldén et al., 2009 | D24: HT | E24: lysholm | F24: 22 | G24: 79.16 | H24: 13.35 | I24: =H24/(SQRT(F24))*1.96 -> 5.5786099 | J24: =G24-I24 -> 73.58139 | K24: =G24+I24 -> 84.73861 | L24: =TEXT(I24,"#0.00") -> 5.58 | M24: =TEXT(J24,"#0.00") -> 73.58 | N24: =TEXT(G24,"#0.00")&" ["&L24&", "&M24&"]" -> 79.16 [5.58, 73.58]
A25: 0 | B25: 3 | C25: Ahldén et al., 2009 | D25: BPTB vs. HT | E25: lysholm | F25: 47 | G25: 0.084 | H25: 0.292 | I25: =H25*1.96 -> 0.57232 | J25: =G25-I25 -> -0.48832 | K25: =G25+I25 -> 0.65632 | L25: =TEXT(I25,"#0.00") -> 0.57 | M25: =TEXT(J25,"#0.00") -> -0.49 | N25: =TEXT(G25,"#0.00")&" ["&L25&", "&M25&"]" -> 0.08 [0.57, -0.49]
A26: 436 | B26: 3 | C26: Ahldén et al., 2009 | D26: BPTB | E26: tegner | F26: 25 | G26: 4.87 | H26: 2.29 | I26: =H26/(SQRT(F26))*1.96 -> 0.89768 | J26: =G26-I26 -> 3.97232 | K26: =G26+I26 -> 5.76768 | L26: =TEXT(I26,"#0.00") -> 0.90 | M26: =TEXT(J26,"#0.00") -> 3.97 | N26: =TEXT(G26,"#0.00")&" ["&L26&", "&M26&"]" -> 4.87 [0.90, 3.97]
A27: 437 | B27: 3 | C27: Ahldén et al., 2009 | D27: HT | E27: tegner | F27: 22 | G27: 4.86 | H27: 1.31 | I27: =H27/(SQRT(F27))*1.96 -> 0.54741416 | J27: =G27-I27 -> 4.3125858 | K27: =G27+I27 -> 5.4074142 | L27: =TEXT(I27,"#0.00") -> 0.55 | M27: =TEXT(J27,"#0.00") -> 4.31 | N27: =TEXT(G27,"#0.00")&" ["&L27&", "&M27&"]" -> 4.86 [0.55, 4.31]
A28: 1 | B28: 3 | C28: Ahldén et al., 2009 | D28: BPTB vs. HT | E28: tegner | F28: 47 | G28: 0.005 | H28: 0.292 | I28: =H28*1.96 -> 0.57232 | J28: =G28-I28 -> -0.56732 | K28: =G28+I28 -> 0.57732 | L28: =TEXT(I28,"#0.00") -> 0.57 | M28: =TEXT(J28,"#0.00") -> -0.57 | N28: =TEXT(G28,"#0.00")&" ["&L28&", "&M28&"]" -> 0.01 [0.57, -0.57]
A29: 130 | B29: 5 | C29: Anderson et al., 2001 | D29: BPTB | E29: instrumented_laxity | F29: 35 | G29: 2.1 | H29: 2 | I29: =H29/(SQRT(F29))*1.96 -> 0.66260094 | J29: =G29-I29 -> 1.4373991 | K29: =G29+I29 -> 2.7626009 | L29: =TEXT(I29,"#0.00") -> 0.66 | M29: =TEXT(J29,"#0.00") -> 1.44 | N29: =TEXT(G29,"#0.00")&" ["&L29&", "&M29&"]" -> 2.10 [0.66, 1.44]
A30: 131 | B30: 5 | C30: Anderson et al., 2001 | D30: HT | E30: instrumented_laxity | F30: 33 | G30: 3.1 | H30: 2.3 | I30: =H30/(SQRT(F30))*1.96 -> 0.78474207 | J30: =G30-I30 -> 2.3152579 | K30: =G30+I30 -> 3.8847421 | L30: =TEXT(I30,"#0.00") -> 0.78 | M30: =TEXT(J30,"#0.00") -> 2.32 | N30: =TEXT(G30,"#0.00")&" ["&L30&", "&M30&"]" -> 3.10 [0.78, 2.32]
A31: 2 | B31: 5 | C31: Anderson et al., 2001 | D31: BPTB vs. HT | E31: instrumented_laxity | F31: 68 | G31: 0.465 | H31: 0.246 | I31: =H31*1.96 -> 0.48216 | J31: =G31-I31 -> -0.01716 | K31: =G31+I31 -> 0.94716 | L31: =TEXT(I31,"#0.00") -> 0.48 | M31: =TEXT(J31,"#0.00") -> -0.02 | N31: =TEXT(G31,"#0.00")&" ["&L31&", "&M31&"]" -> 0.47 [0.48, -0.02]
A32: 372 | B32: 5 | C32: Anderson et al., 2001 | D32: BPTB | E32: pivot_shift_1 | F32: 35 | G32: 18 | H32: 1.59 | I32: =H32/(SQRT(F32))*1.96 -> 0.52676774 | J32: =G32-I32 -> 17.473232 | K32: =G32+I32 -> 18.526768 | L32: =TEXT(I32,"#0.00") -> 0.53 | M32: =TEXT(J32,"#0.00") -> 17.47 | N32: =TEXT(G32,"#0.00")&" ["&L32&", "&M32&"]" -> 18.00 [0.53, 17.47]
A33: 373 | B33: 5 | C33: Anderson et al., 2001 | D33: HT | E33: pivot_shift_1 | F33: 33 | G33: 36 | H33: 1.95 | I33: =H33/(SQRT(F33))*1.96 -> 0.6653248 | J33: =G33-I33 -> 35.334675 | K33: =G33+I33 -> 36.665325 | L33: =TEXT(I33,"#0.00") -> 0.67 | M33: =TEXT(J33,"#0.00") -> 35.33 | N33: =TEXT(G33,"#0.00")&" ["&L33&", "&M33&"]" -> 36.00 [0.67, 35.33]
A34: 1 | B34: 5 | C34: Anderson et al., 2001 | D34: BPTB vs. HT | E34: pivot_shift_1 | F34: 69 | G34: -0.089 | I34: =H34*1.96 -> 0 | J34: =G34-I34 -> -0.089 | K34: =G34+I34 -> -0.089 | L34: =TEXT(I34,"#0.00") -> 0.00 | M34: =TEXT(J34,"#0.00") -> -0.09 | N34: =TEXT(G34,"#0.00")&" ["&L34&", "&M34&"]" -> -0.09 [0.00, -0.09]
A35: 550 | B35: 5 | C35: Anderson et al., 2001 | D35: BPTB | E35: pivot_shift_2 | F35: 35 | G35: 15 | H35: 1.59 | I35: =H35/(SQRT(F35))*1.96 -> 0.52676774 | J35: =G35-I35 -> 14.473232 | K35: =G35+I35 -> 15.526768 | L35: =TEXT(I35,"#0.00") -> 0.53 | M35: =TEXT(J35,"#0.00") -> 14.47 | N35: =TEXT(G35,"#0.00")&" ["&L35&", "&M35&"]" -> 15.00 [0.53, 14.47]
A36: 551 | B36: 5 | C36: Anderson et al., 2001 | D36: HT | E36: pivot_shift_2 | F36: 33 | G36: 27 | H36: 1.95 | I36: =H36/(SQRT(F36))*1.96 -> 0.6653248 | J36: =G36-I36 -> 26.334675 | K36: =G36+I36 -> 27.665325 | L36: =TEXT(I36,"#0.00") -> 0.67 | M36: =TEXT(J36,"#0.00") -> 26.33 | N36: =TEXT(G36,"#0.00")&" ["&L36&", "&M36&"]" -> 27.00 [0.67, 26.33]
A37: 1 | B37: 5 | C37: Anderson et al., 2001 | D37: BPTB vs. HT | E37: pivot_shift_2 | F37: 69 | G37: 0.169 | H37: 0.56351258 | I37: =H37*1.96 -> 1.1044847 | J37: =G37-I37 -> -0.93548466 | K37: =G37+I37 -> 1.2734847 | L37: =TEXT(I37,"#0.00") -> 1.10 | M37: =TEXT(J37,"#0.00") -> -0.94 | N37: =TEXT(G37,"#0.00")&" ["&L37&", "&M37&"]" -> 0.17 [1.10, -0.94]
A38: 0 | B38: 6 | C38: Anz et al., 2023 | D38: BPTB | E38: graft_failure | F38: 8 | G38: 0 | H38: 0.18 | I38: =H38/(SQRT(F38))*1.96 -> 0.12473364 | J38: =G38-I38 -> -0.12473364 | K38: =G38+I38 -> 0.12473364 | L38: =TEXT(I38,"#0.00") -> 0.12 | M38: =TEXT(J38,"#0.00") -> -0.12 | N38: =TEXT(G38,"#0.00")&" ["&L38&", "&M38&"]" -> 0.00 [0.12, -0.12]
A39: 1 | B39: 6 | C39: Anz et al., 2023 | D39: HT | E39: graft_failure | F39: 8 | G39: 0 | H39: 0.18 | I39: =H39/(SQRT(F39))*1.96 -> 0.12473364 | J39: =G39-I39 -> -0.12473364 | K39: =G39+I39 -> 0.12473364 | L39: =TEXT(I39,"#0.00") -> 0.12 | M39: =TEXT(J39,"#0.00") -> -0.12 | N39: =TEXT(G39,"#0.00")&" ["&L39&", "&M39&"]" -> 0.00 [0.12, -0.12]
A40: 0 | B40: 6 | C40: Anz et al., 2023 | D40: BPTB vs. HT | E40: graft_failure | F40: 17 | G40: 1 | H40: 2.0615528 | I40: =H40*1.96 -> 4.0406435 | J40: =G40-I40 -> -3.0406435 | K40: =G40+I40 -> 5.0406435 | L40: =TEXT(I40,"#0.00") -> 4.04 | M40: =TEXT(J40,"#0.00") -> -3.04 | N40: =TEXT(G40,"#0.00")&" ["&L40&", "&M40&"]" -> 1.00 [4.04, -3.04]
...

Sheet Sheet3
D1: study | E1: subgroup
B2: =_xlfn.TEXTJOIN("; ",TRUE,Sheet1!C2:D2) -> Ageberg et al., 2009; BPTB | C2: {=_xlfn.UNIQUE(B2:B661)} -> Ageberg et al., 2009; BPTB | D2: at | E2: =COUNTIF($E$2:$E$177,D2) -> 1
B3: =_xlfn.TEXTJOIN("; ",TRUE,Sheet1!C3:D3) -> Ageberg et al., 2009; HT | C3: Ageberg et al., 2009; HT | D3: ht vs. at | E3: =COUNTIF($E$2:$E$177,D3) -> 1
B4: =_xlfn.TEXTJOIN("; ",TRUE,Sheet1!C4:D4) -> Ageberg et al., 2009; BPTB vs. HT | C4: Ageberg et al., 2009; BPTB vs. HT | D4: plt | E4: =COUNTIF($E$2:$E$177,D4) -> 3
B5: =_xlfn.TEXTJOIN("; ",TRUE,Sheet1!C5:D5) -> Aglietti et al., 2004; BPTB | C5: Aglietti et al., 2004; BPTB | D5: ht vs. plt | E5: =COUNTIF($E$2:$E$177,D5) -> 3
B6: =_xlfn.TEXTJOIN("; ",TRUE,Sheet1!C6:D6) -> Aglietti et al., 2004; HT | C6: Aglietti et al., 2004; HT | D6: ta | E6: =COUNTIF($E$2:$E$177,D6) -> 4
B7: =_xlfn.TEXTJOIN("; ",TRUE,Sheet1!C7:D7) -> Aglietti et al., 2004; BPTB vs. HT | C7: Aglietti et al., 2004; BPTB vs. HT | D7: bptb vs. qt | E7: =COUNTIF($E$2:$E$177,D7) -> 4
B8: =_xlfn.TEXTJOIN("; ",TRUE,Sheet1!C8:D8) -> Aglietti et al., 2004; BPTB | C8: Ahldén et al., 2009; BPTB | D8: ht vs. ta | E8: =COUNTIF($E$2:$E$177,D8) -> 4
B9: =_xlfn.TEXTJOIN("; ",TRUE,Sheet1!C9:D9) -> Aglietti et al., 2004; HT | C9: Ahldén et al., 2009; HT | D9: ht vs. qt | E9: =COUNTIF($E$2:$E$177,D9) -> 7
B10: =_xlfn.TEXTJOIN("; ",TRUE,Sheet1!C10:D10) -> Aglietti et al., 2004; BPTB vs. HT | C10: Ahldén et al., 2009; BPTB vs. HT | D10: qt | E10: =COUNTIF($E$2:$E$177,D10) -> 10
B11: =_xlfn.TEXTJOIN("; ",TRUE,Sheet1!C11:D11) -> Aglietti et al., 2004; BPTB | C11: Anderson et al., 2001; BPTB | D11: bptb vs. ht | E11: =COUNTIF($E$2:$E$177,D11) -> 40
B12: =_xlfn.TEXTJOIN("; ",TRUE,Sheet1!C12:D12) -> Aglietti et al., 2004; HT | C12: Anderson et al., 2001; HT | D12: bptb | E12: =COUNTIF($E$2:$E$177,D12) -> 44
B13: =_xlfn.TEXTJOIN("; ",TRUE,Sheet1!C13:D13) -> Aglietti et al., 2004; BPTB vs. HT | C13: Anderson et al., 2001; BPTB vs. HT | D13: ht | E13: =COUNTIF($E$2:$E$177,D13) -> 55
B14: =_xlfn.TEXTJOIN("; ",TRUE,Sheet1!C14:D14) -> Aglietti et al., 2004; BPTB | C14: Anz et al., 2023; BPTB | D14: {=_xlfn.TEXTSPLIT(C14,"; ")} -> Anz et al., 2023 | E14: BPTB
B15: =_xlfn.TEXTJOIN("; ",TRUE,Sheet1!C15:D15) -> Aglietti et al., 2004; HT | C15: Anz et al., 2023; HT | D15: {=_xlfn.TEXTSPLIT(C15,"; ")} -> Anz et al., 2023 | E15: HT
B16: =_xlfn.TEXTJOIN("; ",TRUE,Sheet1!C16:D16) -> Aglietti et al., 2004; BPTB vs. HT | C16: Anz et al., 2023; BPTB vs. HT | D16: {=_xlfn.TEXTSPLIT(C16,"; ")} -> Anz et al., 2023 | E16: BPTB vs. HT
B17: =_xlfn.TEXTJOIN("; ",TRUE,Sheet1!C17:D17) -> Aglietti et al., 2004; BPTB | C17: Aune et al., 2001; BPTB | D17: {=_xlfn.TEXTSPLIT(C17,"; ")} -> Aune et al., 2001 | E17: BPTB
B18: =_xlfn.TEXTJOIN("; ",TRUE,Sheet1!C18:D18) -> Aglietti et al., 2004; HT | C18: Aune et al., 2001; HT | D18: {=_xlfn.TEXTSPLIT(C18,"; ")} -> Aune et al., 2001 | E18: HT
B19: =_xlfn.TEXTJOIN("; ",TRUE,Sheet1!C19:D19) -> Aglietti et al., 2004; BPTB vs. HT | C19: Aune et al., 2001; BPTB vs. HT | D19: {=_xlfn.TEXTSPLIT(C19,"; ")} -> Aune et al., 2001 | E19: BPTB vs. HT
B20: =_xlfn.TEXTJOIN("; ",TRUE,Sheet1!C20:D20) -> Ahldén et al., 2009; BPTB | C20: Barenius et al., 2010; BPTB | D20: {=_xlfn.TEXTSPLIT(C20,"; ")} -> Barenius et al., 2010 | E20: BPTB
B21: =_xlfn.TEXTJOIN("; ",TRUE,Sheet1!C21:D21) -> Ahldén et al., 2009; HT | C21: Barenius et al., 2010; HT | D21: {=_xlfn.TEXTSPLIT(C21,"; ")} -> Barenius et al., 2010 | E21: HT
B22: =_xlfn.TEXTJOIN("; ",TRUE,Sheet1!C22:D22) -> Ahldén et al., 2009; BPTB vs. HT | C22: Barenius et al., 2010; BPTB vs. HT | D22: {=_xlfn.TEXTSPLIT(C22,"; ")} -> Barenius et al., 2010 | E22: BPTB vs. HT
B23: =_xlfn.TEXTJOIN("; ",TRUE,Sheet1!C23:D23) -> Ahldén et al., 2009; BPTB | C23: Barié et al., 2020; BPTB | D23: {=_xlfn.TEXTSPLIT(C23,"; ")} -> Barié et al., 2020 | E23: BPTB
B24: =_xlfn.TEXTJOIN("; ",TRUE,Sheet1!C24:D24) -> Ahldén et al., 2009; HT | C24: Barié et al., 2020; QT | D24: {=_xlfn.TEXTSPLIT(C24,"; ")} -> Barié et al., 2020 | E24: QT
B25: =_xlfn.TEXTJOIN("; ",TRUE,Sheet1!C25:D25) -> Ahldén et al., 2009; BPTB vs. HT | C25: Barié et al., 2020; BPTB vs. QT | D25: {=_xlfn.TEXTSPLIT(C25,"; ")} -> Barié et al., 2020 | E25: BPTB vs. QT
... B177: =_xlfn.TEXTJOIN("; ",TRUE,Sheet1!C177:D177) -> Guglielmetti et al., 2021; HT | C177: Zaffagnini et al., 2011; BPTB vs. HT | D177: {=_xlfn.TEXTSPLIT(C177,"; ")} -> Zaffagnini et al., 2011 | E177: BPTB vs. HT
B178: =_xlfn.TEXTJOIN("; ",TRUE,Sheet1!C178:D178) -> Guglielmetti et al., 2021; BPTB vs. HT | D178: {=_xlfn.TEXTSPLIT(C178,"; ")} -> #VALUE!
B179: =_xlfn.TEXTJOIN("; ",TRUE,Sheet1!C179:D179) -> Guglielmetti et al., 2021; BPTB | D179: {=_xlfn.TEXTSPLIT(C179,"; ")} -> #VALUE!
B180: =_xlfn.TEXTJOIN("; ",TRUE,Sheet1!C180:D180) -> Guglielmetti et al., 2021; HT | D180: {=_xlfn.TEXTSPLIT(C180,"; ")} -> #VALUE!
B181: =_xlfn.TEXTJOIN("; ",TRUE,Sheet1!C181:D181) -> Guglielmetti et al., 2021; BPTB vs. HT | D181: {=_xlfn.TEXTSPLIT(C181,"; ")} -> #VALUE!
B182: =_xlfn.TEXTJOIN("; ",TRUE,Sheet1!C182:D182) -> Guglielmetti et al., 2021; BPTB | D182: {=_xlfn.TEXTSPLIT(C182,"; ")} -> #VALUE!
B183: =_xlfn.TEXTJOIN("; ",TRUE,Sheet1!C183:D183) -> Guglielmetti et al., 2021; HT | D183: {=_xlfn.TEXTSPLIT(C183,"; ")} -> #VALUE!
B184: =_xlfn.TEXTJOIN("; ",TRUE,Sheet1!C184:D184) -> Guglielmetti et al., 2021; BPTB vs. HT | D184: {=_xlfn.TEXTSPLIT(C184,"; ")} -> #VALUE!
B185: =_xlfn.TEXTJOIN("; ",TRUE,Sheet1!C185:D185) -> Guglielmetti et al., 2021; BPTB | D185: {=_xlfn.TEXTSPLIT(C185,"; ")} -> #VALUE!
B186: =_xlfn.TEXTJOIN("; ",TRUE,Sheet1!C186:D186) -> Guglielmetti et al., 2021; HT | D186: {=_xlfn.TEXTSPLIT(C186,"; ")} -> #VALUE!
B187: =_xlfn.TEXTJOIN("; ",TRUE,Sheet1!C187:D187) -> Guglielmetti et al., 2021; BPTB vs. HT | D187: {=_xlfn.TEXTSPLIT(C187,"; ")} -> #VALUE!
B188: =_xlfn.TEXTJOIN("; ",TRUE,Sheet1!C188:D188) -> Guglielmetti et al., 2021; BPTB | D188: {=_xlfn.TEXTSPLIT(C188,"; ")} -> #VALUE!
B189: =_xlfn.TEXTJOIN("; ",TRUE,Sheet1!C189:D189) -> Guglielmetti et al., 2021; HT | D189: {=_xlfn.TEXTSPLIT(C189,"; ")} -> #VALUE!
B190: =_xlfn.TEXTJOIN("; ",TRUE,Sheet1!C190:D190) -> Guglielmetti et al., 2021; BPTB vs. HT
B191: =_xlfn.TEXTJOIN("; ",TRUE,Sheet1!C191:D191) -> Harilainen et al., 2006; BPTB
...

Sheet bptb vs. ht
A1: ID | B1: Study | C1: Outcome | D1: Sample size | E1: Effect size estimate | F1: Standard Error
A2: 1 | B2: Ageberg et al., 2009 | C2: tegner | D2: 36 | E2: 0.744 | F2: 0.347 | G2: =1.96*F2 -> 0.68012 | H2: =TEXT(E2-G2,"#0.00") -> 0.06 | I2: =TEXT(E2+G2,"0.00") -> 1.42 | J2: =E2&" ["&H2&", "&I2&"]" -> 0.744 [0.06, 1.42]
A3: 2 | B3: Aglietti et al., 2004 | C3: instrumented_laxity | D3: 120 | E3: 0.209 | F3: 0.183 | G3: =1.96*F3 -> 0.35868 | H3: =TEXT(E3-G3,"#0.00") -> -0.15 | I3: =TEXT(E3+G3,"0.00") -> 0.57 | J3: =E3&" ["&H3&", "&I3&"]" -> 0.209 [-0.15, 0.57]
A4: 2 | C4: lachman_1 | D4: 121 | E4: 1 | F4: 2.008316 | G4: =1.96*F4 -> 3.9362994 | H4: =TEXT(E4-G4,"#0.00") -> -2.94 | I4: =TEXT(E4+G4,"0.00") -> 4.94 | J4: =E4&" ["&H4&", "&I4&"]" -> 1 [-2.94, 4.94]
A5: 2 | C5: lachman_2 | D5: 121 | E5: 1 | F5: 2.008316 | G5: =1.96*F5 -> 3.9362994 | H5: =TEXT(E5-G5,"#0.00") -> -2.94 | I5: =TEXT(E5+G5,"0.00") -> 4.94 | J5: =E5&" ["&H5&", "&I5&"]" -> 1 [-2.94, 4.94]
A6: 2 | C6: pivot_shift_1 | D6: 121 | E6: 0.895 | F6: 0.47180799 | G6: =1.96*F6 -> 0.92474366 | H6: =TEXT(E6-G6,"#0.00") -> -0.03 | I6: =TEXT(E6+G6,"0.00") -> 1.82 | J6: =E6&" ["&H6&", "&I6&"]" -> 0.895 [-0.03, 1.82]
A7: 2 | C7: pivot_shift_2 | D7: 121 | E7: 1 | F7: 2.008316 | G7: =1.96*F7 -> 3.9362994 | H7: =TEXT(E7-G7,"#0.00") -> -2.94 | I7: =TEXT(E7+G7,"0.00") -> 4.94 | J7: =E7&" ["&H7&", "&I7&"]" -> 1 [-2.94, 4.94]
A8: 3 | B8: Ahldén et al., 2009 | C8: instrumented_laxity | D8: 47 | E8: 0.401 | F8: 0.295 | G8: =1.96*F8 -> 0.5782 | H8: =TEXT(E8-G8,"#0.00") -> -0.18 | I8: =TEXT(E8+G8,"0.00") -> 0.98 | J8: =E8&" ["&H8&", "&I8&"]" -> 0.401 [-0.18, 0.98]
A9: 3 | C9: lysholm | D9: 47 | E9: 0.084 | F9: 0.292 | G9: =1.96*F9 -> 0.57232 | H9: =TEXT(E9-G9,"#0.00") -> -0.49 | I9: =TEXT(E9+G9,"0.00") -> 0.66 | J9: =E9&" ["&H9&", "&I9&"]" -> 0.084 [-0.49, 0.66]
A10: 3 | C10: tegner | D10: 47 | E10: 0.005 | F10: 0.292 | G10: =1.96*F10 -> 0.57232 | H10: =TEXT(E10-G10,"#0.00") -> -0.57 | I10: =TEXT(E10+G10,"0.00") -> 0.58 | J10: =E10&" ["&H10&", "&I10&"]" -> 0.005 [-0.57, 0.58]
A11: 5 | B11: Anderson et al., 2001 | C11: instrumented_laxity | D11: 68 | E11: 0.465 | F11: 0.246 | G11: =1.96*F11 -> 0.48216 | H11: =TEXT(E11-G11,"#0.00") -> -0.02 | I11: =TEXT(E11+G11,"0.00") -> 0.95 | J11: =E11&" ["&H11&", "&I11&"]" -> 0.465 [-0.02, 0.95]
A12: 5 | C12: pivot_shift_1 | D12: 69 | E12: -0.089 | G12: =1.96*F12 -> 0 | H12: =TEXT(E12-G12,"#0.00") -> -0.09 | I12: =TEXT(E12+G12,"0.00") -> -0.09 | J12: =E12&" ["&H12&", "&I12&"]" -> -0.089 [-0.09, -0.09]
A13: 5 | C13: pivot_shift_2 | D13: 69 | E13: 0.169 | F13: 0.56351258 | G13: =1.96*F13 -> 1.1044847 | H13: =TEXT(E13-G13,"#0.00") -> -0.94 | I13: =TEXT(E13+G13,"0.00") -> 1.27 | J13: =E13&" ["&H13&", "&I13&"]" -> 0.169 [-0.94, 1.27]
A14: 6 | B14: Anz et al., 2023 | C14: graft_failure | D14: 17 | E14: 1 | F14: 2.0615528 | G14: =1.96*F14 -> 4.0406435 | H14: =TEXT(E14-G14,"#0.00") -> -3.04 | I14: =TEXT(E14+G14,"0.00") -> 5.04 | J14: =E14&" ["&H14&", "&I14&"]" -> 1 [-3.04, 5.04]
A15: 7 | B15: Aune et al., 2001 | C15: instrumented_laxity | D15: 61 | E15: 0.16 | F15: 0.257 | G15: =1.96*F15 -> 0.50372 | H15: =TEXT(E15-G15,"#0.00") -> -0.34 | I15: =TEXT(E15+G15,"0.00") -> 0.66 | J15: =E15&" ["&H15&", "&I15&"]" -> 0.16 [-0.34, 0.66]
A16: 9 | B16: Barenius et al., 2010 | C16: lysholm | D16: 153 | E16: 0.049 | F16: 0.162 | G16: =1.96*F16 -> 0.31752 | H16: =TEXT(E16-G16,"#0.00") -> -0.27 | I16: =TEXT(E16+G16,"0.00") -> 0.37 | J16: =E16&" ["&H16&", "&I16&"]" -> 0.049 [-0.27, 0.37]
A17: 9 | C17: tegner | D17: 153 | E17: 0.923 | F17: 0.17 | G17: =1.96*F17 -> 0.3332 | H17: =TEXT(E17-G17,"#0.00") -> 0.59 | I17: =TEXT(E17+G17,"0.00") -> 1.26 | J17: =E17&" ["&H17&", "&I17&"]" -> 0.923 [0.59, 1.26]
A18: 11 | B18: Beynnon et al., 2002 | C18: lachman_1 | D18: 45 | E18: 0.146 | F18: 0.85671797 | G18: =1.96*F18 -> 1.6791672 | H18: =TEXT(E18-G18,"#0.00") -> -1.53 | I18: =TEXT(E18+G18,"0.00") -> 1.83 | J18: =E18&" ["&H18&", "&I18&"]" -> 0.146 [-1.53, 1.83]
A19: 11 | C19: lachman_2 | D19: 45 | E19: 3 | F19: 0.62063289 | G19: =1.96*F19 -> 1.2164405 | H19: =TEXT(E19-G19,"#0.00") -> 1.78 | I19: =TEXT(E19+G19,"0.00") -> 4.22 | J19: =E19&" ["&H19&", "&I19&"]" -> 3 [1.78, 4.22]
A20: 11 | C20: pivot_shift_1 | D20: 45 | E20: 0.252 | F20: 0.72147911 | G20: =1.96*F20 -> 1.414099 | H20: =TEXT(E20-G20,"#0.00") -> -1.16 | I20: =TEXT(E20+G20,"0.00") -> 1.67 | J20: =E20&" ["&H20&", "&I20&"]" -> 0.252 [-1.16, 1.67]
A21: 11 | C21: pivot_shift_2 | D21: 45 | E21: 5.688 | F21: 0.96469263 | G21: =1.96*F21 -> 1.8907976 | H21: =TEXT(E21-G21,"#0.00") -> 3.80 | I21: =TEXT(E21+G21,"0.00") -> 7.58 | J21: =E21&" ["&H21&", "&I21&"]" -> 5.688 [3.80, 7.58]
A22: 13 | B22: Björnsson et al., 2016 | C22: ikdc_subjective | D22: 147 | E22: 0.341 | F22: 0.169 | G22: =1.96*F22 -> 0.33124 | H22: =TEXT(E22-G22,"#0.00") -> 0.01 | I22: =TEXT(E22+G22,"0.00") -> 0.67 | J22: =E22&" ["&H22&", "&I22&"]" -> 0.341 [0.01, 0.67]
A23: 13 | C23: lachman_1 | D23: 148 | E23: 0.276 | F23: 0.36774102 | G23: =1.96*F23 -> 0.72077241 | H23: =TEXT(E23-G23,"#0.00") -> -0.44 | I23: =TEXT(E23+G23,"0.00") -> 1.00 | J23: =E23&" ["&H23&", "&I23&"]" -> 0.276 [-0.44, 1.00]
A24: 13 | C24: lachman_2 | D24: 148 | E24: 0.42 | F24: 0.46232899 | G24: =1.96*F24 -> 0.90616482 | H24: =TEXT(E24-G24,"#0.00") -> -0.49 | I24: =TEXT(E24+G24,"0.00") -> 1.33 | J24: =E24&" ["&H24&", "&I24&"]" -> 0.42 [-0.49, 1.33]
A25: 13 | C25: lysholm | D25: 147 | E25: 0.081 | F25: 0.167 | G25: =1.96*F25 -> 0.32732 | H25: =TEXT(E25-G25,"#0.00") -> -0.25 | I25: =TEXT(E25+G25,"0.00") -> 0.41 | J25: =E25&" ["&H25&", "&I25&"]" -> 0.081 [-0.25, 0.41]
A26: 13 | C26: pivot_shift_1 | D26: 148 | E26: 1.541 | F26: 0.34443632 | G26: =1.96*F26 -> 0.67509518 | H26: =TEXT(E26-G26,"#0.00") -> 0.87 | I26: =TEXT(E26+G26,"0.00") -> 2.22 | J26: =E26&" ["&H26&", "&I26&"]" -> 1.541 [0.87, 2.22]
A27: 13 | C27: pivot_shift_2 | D27: 148 | E27: 1.379 | F27: 0.43379819 | G27: =1.96*F27 -> 0.85024445 | H27: =TEXT(E27-G27,"#0.00") -> 0.53 | I27: =TEXT(E27+G27,"0.00") -> 2.23 | J27: =E27&" ["&H27&", "&I27&"]" -> 1.379 [0.53, 2.23]
A28: 13 | C28: tegner | D28: 147 | E28: 0.059 | F28: 0.167 | G28: =1.96*F28 -> 0.32732 | H28: =TEXT(E28-G28,"#0.00") -> -0.27 | I28: =TEXT(E28+G28,"0.00") -> 0.39 | J28: =E28&" ["&H28&", "&I28&"]" -> 0.059 [-0.27, 0.39]
A29: 23 | B29: Ejerhed et al., 2003 | C29: instrumented_laxity | D29: 66 | E29: 0.048 | F29: 0.246 | G29: =1.96*F29 -> 0.48216 | H29: =TEXT(E29-G29,"#0.00") -> -0.43 | I29: =TEXT(E29+G29,"0.00") -> 0.53 | J29: =E29&" ["&H29&", "&I29&"]" -> 0.048 [-0.43, 0.53]
A30: 23 | C30: lachman_1 | D30: 67 | E30: 0.697 | F30: 0.49099402 | G30: =1.96*F30 -> 0.96234828 | H30: =TEXT(E30-G30,"#0.00") -> -0.27 | I30: =TEXT(E30+G30,"0.00") -> 1.66 | J30: =E30&" ["&H30&", "&I30&"]" -> 0.697 [-0.27, 1.66]
A31: 23 | C31: lachman_2 | D31: 67 | E31: 5.667 | F31: 1.5693136 | G31: =1.96*F31 -> 3.0758546 | H31: =TEXT(E31-G31,"#0.00") -> 2.59 | I31: =TEXT(E31+G31,"0.00") -> 8.74 | J31: =E31&" ["&H31&", "&I31&"]" -> 5.667 [2.59, 8.74]
A32: 23 | C32: lysholm | D32: 66 | E32: 0.256 | F32: 0.247 | G32: =1.96*F32 -> 0.48412 | H32: =TEXT(E32-G32,"#0.00") -> -0.23 | I32: =TEXT(E32+G32,"0.00") -> 0.74 | J32: =E32&" ["&H32&", "&I32&"]" -> 0.256 [-0.23, 0.74]
A33: 23 | C33: tegner | D33: 66 | E33: 0.366 | F33: 0.248 | G33: =1.96*F33 -> 0.48608 | H33: =TEXT(E33-G33,"#0.00") -> -0.12 | I33: =TEXT(E33+G33,"0.00") -> 0.85 | J33: =E33&" ["&H33&", "&I33&"]" -> 0.366 [-0.12, 0.85]
A34: 25 | B34: Eriksson et al., 2001 | C34: instrumented_laxity | D34: 89 | E34: 0.161 | F34: 0.213 | G34: =1.96*F34 -> 0.41748 | H34: =TEXT(E34-G34,"#0.00") -> -0.26 | I34: =TEXT(E34+G34,"0.00") -> 0.58 | J34: =E34&" ["&H34&", "&I34&"]" -> 0.161 [-0.26, 0.58]
A35: 25 | C35: pivot_shift_1 | D35: 90 | E35: 0.259 | F35: 0.51828589 | G35: =1.96*F35 -> 1.0158404 | H35: =TEXT(E35-G35,"#0.00") -> -0.76 | I35: =TEXT(E35+G35,"0.00") -> 1.27 | J35: =E35&" ["&H35&", "&I35&"]" -> 0.259 [-0.76, 1.27]
A36: 25 | C36: pivot_shift_2 | D36: 90 | E36: 1.119 | F36: 2.0112399 | G36: =1.96*F36 -> 3.9420303 | H36: =TEXT(E36-G36,"#0.00") -> -2.82 | I36: =TEXT(E36+G36,"0.00") -> 5.06 | J36: =E36&" ["&H36&", "&I36&"]" -> 1.119 [-2.82, 5.06]
A37: 26 | B37: Feller & Webster, 2003 | C37: instrumented_laxity | D37: 48 | E37: 0.55 | F37: 0.297 | G37: =1.96*F37 -> 0.58212 | H37: =TEXT(E37-G37,"#0.00") -> -0.03 | I37: =TEXT(E37+G37,"0.00") -> 1.13 | J37: =E37&" ["&H37&", "&I37&"]" -> 0.55 [-0.03, 1.13]
A38: 26 | C38: lachman_1 | D38: 49 | E38: 0.032 | F38: 0.86761008 | G38: =1.96*F38 -> 1.7005158 | H38: =TEXT(E38-G38,"#0.00") -> -1.67 | I38: =TEXT(E38+G38,"0.00") -> 1.73 | J38: =E38&" ["&H38&", "&I38&"]" -> 0.032 [-1.67, 1.73]
A39: 26 | C39: lachman_2 | D39: 49 | E39: 0.778 | F39: 2.0210532 | G39: =1.96*F39 -> 3.9612643 | H39: =TEXT(E39-G39,"#0.00") -> -3.18 | I39: =TEXT(E39+G39,"0.00") -> 4.74 | J39: =E39&" ["&H39&", "&I39&"]" -> 0.778 [-3.18, 4.74]
A40: 26 | C40: pivot_shift_1 | D40: 49 | E40: 0.126 | F40: 0.79284077 | G40: =1.96*F40 -> 1.5539679 | H40: =TEXT(E40-G40,"#0.00") -> -1.43 | I40: =TEXT(E40+G40,"0.00") -> 1.68 | J40: =E40&" ["&H40&", "&I40&"]" -> 0.126 [-1.43, 1.68]
...
